Workbook

Sheet Posicion Inicial Gallo
A1: tipo_especie | B1: Ticker | C1: especie | D1: Codigo especie | E1: Codigo Especie Origen | F1: comentario especies | G1: detalle | H1: custodia | I1: cantidad | J1: precio Tenencia Inicial Pesos | K1: precio Tenencia Inicial USD | L1: Precio de PreciosIniciales | M1: precio costo(en proceso) | N1: Origen precio costo | O1: comentarios precio costo | P1: Precio a Utilizar | Q1: importe_pesos | R1: porc_cartera_pesos | S1: importe_dolares | T1: porc_cartera_dolares | U1: Tipo Instrumento | V1: Precio Nominal
A2: RENTA FIJA EN DOLARES | B2: BPOA7 | C2: BOPREAL S. 1 A VTO31/10/27 U$S CG | D2: 9234 | E2: PreciosInicialesEspecies | H2: CAJA VALORES | I2: 613798 | J2: 112460 | K2: 0.96300281 | L2: 112100 | N2: PrecioTenenciasIniciales | P2: 1001.513 | Q2: 6.9027723e+08 | R2: 515.16 | S2: 591089.2 | T2: 515.16 | U2: Títulos Públicos | V2: 1001.513
A3: RENTA FIJA EN DOLARES | B3: FUTUROS | D3: 56996 | E3: EspeciesGallo | J3: 0 | K3: 0 | L3: 0 | N3: PreciosInicialesEspecies | P3: 0 | U3: Obligaciones Negociables | V3: 0
A4: RENTA FIJA EN DOLARES | B4: DLR012025 | C4: DLR012025 | E4: NoEncontrado | H4: CAJA VALORES | I4: -200 | J4: 0 | K4: 0 | L4: 0 | N4: PreciosInicialesEspecies | P4: 0 | V4: 0
A5: CASH | B5: PESOS | C5: PESOS | G5: Cuenta Corriente | I5: -1125781.2 | J5: 1 | K5: 0.00085630314 | L5: 1 | N5: PreciosInicialesEspecies | P5: 1 | Q5: -1125781.2 | R5: -0.84 | S5: -964.01 | T5: -0.84 | V5: 1
A6: CASH | B6: DOLARES | C6: DOLARES | G6: Cuenta Corriente | I6: -475386.47 | J6: 1167.8055 | K6: 1 | L6: 1167.806 | N6: PreciosInicialesEspecies | P6: 1167.806 | Q6: -5.5515894e+08 | R6: -414.32 | S6: -475386.47 | T6: -414.32 | V6: 1167.806

Sheet Posicion Final Gallo
A1: tipo_especie | B1: Ticker | C1: especie | D1: Codigo especie | E1: Codigo Especie Origen | F1: comentario especies | G1: detalle | H1: custodia | I1: cantidad | J1: precio Tenencia Final Pesos | K1: precio Tenencia Final USD | L1: Precio Tenencia Inicial | M1: precio costo(en proceso) | N1: Origen precio costo | O1: comentarios precio costo | P1: Precio a Utilizar | Q1: importe_pesos | R1: porc_cartera_pesos | S1: importe_dolares | T1: porc_cartera_dolares | U1: Tipo Instrumento | V1: Precio Nominal
A2: RENTA FIJA EN PESOS | B2: TZV/25 | C2: BONO TESORO NACIONAL 30/06/25 U$S CG | D2: 9245 | E2: EspeciesGallo | H2: CAJA VALORES | I2: 200000 | J2: 1172.5 | K2: 0.9825732 | L2: 0 | N2: PreciosInicialesEspecies | P2: 0 | Q2: 234500000 | R2: 51.61 | S2: 196514.64 | T2: 51.61 | U2: Títulos Públicos | V2: 0
A3: RENTA FIJA EN DOLARES | B3: BPOB7 | C3: BOPREAL S. 1 B VTO31/10/27 U$S CG | D3: 9235 | E3: PreciosInicialesEspecies | H3: CAJA VALORES | I3: 205824 | J3: 1155.1 | K3: 0.96799173 | L3: 105910 | N3: PreciosInicialesEspecies | P3: 105910 | Q3: 2.377473e+08 | R3: 52.33 | S3: 199235.93 | T3: 52.33 | U3: Títulos Públicos | V3: 1059.1
A4: RENTA FIJA EN DOLARES | B4: FUTUROS | D4: 56996 | E4: EspeciesGallo | J4: 0 | K4: 0 | L4: 0 | N4: PreciosInicialesEspecies | P4: 0 | U4: Obligaciones Negociables | V4: 0
A5: RENTA FIJA EN DOLARES | B5: DLR062025 | C5: DLR062025 | E5: NoEncontrado | H5: CAJA VALORES | I5: -200 | J5: 0 | K5: 0 | L5: 0 | N5: PreciosInicialesEspecies | P5: 0 | V5: 0
A6: CASH | B6: PESOS | C6: PESOS | G6: Cuenta Corriente | I6: -2.3696646e+08 | J6: 0 | K6: 0 | L6: 1 | N6: PreciosInicialesEspecies | P6: 1 | V6: 1
A7: CASH | B7: DOLARES | C7: DOLARES | G7: Cuenta Corriente | I7: -14984.4 | J7: 1193.2953 | K7: 1 | L7: 1167.806 | N7: PreciosInicialesEspecies | P7: 1167.806 | Q7: -17880814 | R7: -3.94 | S7: -14984.4 | T7: -3.94 | V7: 1167.806

Sheet Boletos
A1: Tipo de Instrumento | B1: Concertación | C1: Liquidación | D1: Nro. Boleto | E1: Moneda | F1: Tipo Operación | G1: Cod.Instrum | H1: Instrumento Crudo | I1: InstrumentoConMoneda | J1: Cantidad | K1: Precio | L1: Tipo Cambio | M1: Bruto | N1: Interés | O1: Gastos | P1: Neto Calculado | Q1: Origen | R1: moneda emision | S1: Auditoría | T1: Precio Nominal
A2: Títulos Públicos | B2: 45733 | D2: 30874 | E2: Pesos | F2: COMPRA | G2: 9256 | H2: LT REP ARGENTINA CAP $ V31/03/25 | I2: LT REP ARGENTINA CAP $ V31/03/25 - Pesos | J2: 16000000 | K2: 156 | L2: 1 | M2: 24960000 | N2: 0 | O2: 0 | P2: 24960000 | Q2: gallo-Renta Fija Pesos | R2: Pesos | S2: Origen: Gallo-Renta Fija Pesos | Fecha: 17/03/25 | Cod: 09256 | Op: COMPRA | T2: 1.56
A3: Títulos Públicos | B3: 45734 | D3: 31254 | E3: Pesos | F3: VENTA | G3: 9256 | H3: LT REP ARGENTINA CAP $ V31/03/25 | I3: LT REP ARGENTINA CAP $ V31/03/25 - Pesos | J3: -16000000 | K3: 136.031 | L3: 1 | M3: -21764960 | N3: 0 | O3: 0 | P3: -21764960 | Q3: gallo-Renta Fija Pesos | R3: Pesos | S3: Origen: Gallo-Renta Fija Pesos | Fecha: 18/03/25 | Cod: 09256 | Op: VENTA | T3: 1.36031
A4: Títulos Públicos | B4: 45768 | D4: 44452 | E4: Dolar MEP | F4: COMPRA | G4: 5921 | H4: BONO USD 2030 LA | I4: BONO REP. ARGENTINA USD STEP UP 2030 - Dolar MEP (local) | J4: 150056 | K4: 64.692 | L4: 1122.08 | M4: 97074.228 | N4: 0 | O4: 0 | P4: 97074.228 | Q4: gallo-Renta Fija Dolares | R4: Dolar MEP (local) | S4: Origen: Gallo-Renta Fija Dolares | Fecha: 21/04/25 | Cod: 05921 | Op: COMPRA | T4: 0.64692
A5: Títulos Públicos | B5: 45768 | D5: 44453 | E5: Dolar MEP | F5: VENTA USD | G5: 5921 | H5: BONO USD 2030 LA | I5: BONO REP. ARGENTINA USD STEP UP 2030 - Dolar MEP (local) | J5: -150056 | K5: 66.479 | L5: 1122.08 | M5: -99755.728 | N5: 0 | O5: 0 | P5: -99755.728 | Q5: gallo-Renta Fija Dolares | R5: Dolar MEP (local) | S5: Origen: Gallo-Renta Fija Dolares | Fecha: 21/04/25 | Cod: 05921 | Op: VENTA USD | T5: 0.66479
A6: Títulos Públicos | B6: 45769 | D6: 44402 | E6: Dolar MEP | F6: VENTA USD | G6: 9234 | H6: BOPREAL S. 1 A VTO31/10/27 U$S CG | I6: BOPREAL S. 1 A VTO31/10/27 U$S CG - Dolar MEP (local) | J6: -200000 | K6: 100 | L6: 1140.38 | M6: -200000 | N6: 0 | O6: 0 | P6: -200000 | Q6: gallo-Renta Fija Dolares | R6: Dolar MEP (local) | S6: Origen: Gallo-Renta Fija Dolares | Fecha: 22/04/25 | Cod: 09234 | Op: VENTA USD | T6: 1
A7: Títulos Públicos | B7: 45769 | D7: 44405 | E7: Dolar MEP | F7: VENTA | G7: 9234 | H7: BOPREAL S. 1 A VTO31/10/27 U$S CG | I7: BOPREAL S. 1 A VTO31/10/27 U$S CG - Dolar MEP (local) | J7: -100000 | K7: 95.799 | L7: 1140.38 | M7: -95799 | N7: 0 | O7: 0 | P7: -95799 | Q7: gallo-Renta Fija Dolares | R7: Dolar MEP (local) | S7: Origen: Gallo-Renta Fija Dolares | Fecha: 22/04/25 | Cod: 09234 | Op: VENTA | T7: 0.95799
A8: Títulos Públicos | B8: 45770 | D8: 44957 | E8: Dolar MEP | F8: VENTA USD | G8: 9234 | H8: BOPREAL S. 1 A VTO31/10/27 U$S CG | I8: BOPREAL S. 1 A VTO31/10/27 U$S CG - Dolar MEP (local) | J8: -16458 | K8: 100 | L8: 1168 | M8: -16458 | N8: 0 | O8: 0 | P8: -16458 | Q8: gallo-Renta Fija Dolares | R8: Dolar MEP (local) | S8: Origen: Gallo-Renta Fija Dolares | Fecha: 23/04/25 | Cod: 09234 | Op: VENTA USD | T8: 1
A9: Títulos Públicos | B9: 45771 | D9: 45873 | E9: Dolar MEP | F9: VENTA USD | G9: 9234 | H9: BOPREAL S. 1 A VTO31/10/27 U$S CG | I9: BOPREAL S. 1 A VTO31/10/27 U$S CG - Dolar MEP (local) | J9: -85547 | K9: 100.012 | L9: 1186.53 | M9: -85557.266 | N9: 0 | O9: 0 | P9: -85557.266 | Q9: gallo-Renta Fija Dolares | R9: Dolar MEP (local) | S9: Origen: Gallo-Renta Fija Dolares | Fecha: 24/04/25 | Cod: 09234 | Op: VENTA USD | T9: 1.00012
A10: Títulos Públicos | B10: 45772 | D10: 46252 | E10: Dolar MEP | F10: VENTA USD | G10: 9234 | H10: BOPREAL S. 1 A VTO31/10/27 U$S CG | I10: BOPREAL S. 1 A VTO31/10/27 U$S CG - Dolar MEP (local) | J10: -211793 | K10: 100.25 | L10: 1184.24 | M10: -212322.48 | N10: 0 | O10: 0 | P10: -212322.48 | Q10: gallo-Renta Fija Dolares | R10: Dolar MEP (local) | S10: Origen: Gallo-Renta Fija Dolares | Fecha: 25/04/25 | Cod: 09234 | Op: VENTA USD | T10: 1.0025
A11: Títulos Públicos | B11: 45784 | D11: 50504 | E11: Pesos | F11: COMPRA | G11: 9311 | H11: BONO TESORO NACION AJ CER V30/5/25 $ CG | I11: BONO TESORO NACION AJ CER V30/5/25 $ CG - Pesos | J11: 90867961 | K11: 122.982 | L11: 1 | M11: 1.1175124e+08 | N11: 0 | O11: 0 | P11: 1.1175124e+08 | Q11: gallo-Renta Fija Pesos | R11: Pesos | S11: Origen: Gallo-Renta Fija Pesos | Fecha: 07/05/25 | Cod: 09311 | Op: COMPRA | T11: 1.22982
A12: Títulos Públicos | B12: 45784 | D12: 50489 | E12: Pesos | F12: VENTA | G12: 9311 | H12: BONO TESORO NACION AJ CER V30/5/25 $ CG | I12: BONO TESORO NACION AJ CER V30/5/25 $ CG - Pesos | J12: -90867961 | K12: 118.244 | L12: 1 | M12: -1.0744591e+08 | N12: 0 | O12: 0 | P12: -1.0744591e+08 | Q12: gallo-Renta Fija Pesos | R12: Pesos | S12: Origen: Gallo-Renta Fija Pesos | Fecha: 07/05/25 | Cod: 09311 | Op: VENTA | T12: 1.18244
A13: Títulos Públicos | B13: 45796 | D13: 55534 | E13: Dolar MEP | F13: COMPRA | G13: 5921 | H13: BONO USD 2030 LA | I13: BONO REP. ARGENTINA USD STEP UP 2030 - Dolar MEP (local) | J13: 140242 | K13: 67.74 | L13: 1148.77 | M13: 94999.931 | N13: 0 | O13: 0 | P13: 94999.931 | Q13: gallo-Renta Fija Dolares | R13: Dolar MEP (local) | S13: Origen: Gallo-Renta Fija Dolares | Fecha: 19/05/25 | Cod: 05921 | Op: COMPRA | T13: 0.6774
... A16: Títulos Públicos | B16: 45799 | D16: 57372 | E16: Dolar MEP | F16: VENTA | G16: 5921 | H16: BONO USD 2030 LA | I16: BONO REP. ARGENTINA USD STEP UP 2030 - Dolar MEP (local) | J16: -144117 | K16: 67.854 | L16: 1143.49 | M16: -97789.149 | N16: 0 | O16: 0 | P16: -97789.149 | Q16: gallo-Renta Fija Dolares | R16: Dolar MEP (local) | S16: Origen: Gallo-Renta Fija Dolares | Fecha: 22/05/25 | Cod: 05921 | Op: VENTA | T16: 0.67854
A17: Títulos Públicos | B17: 45807 | C17: 2/6/2025 | D17: 23030 | E17: Pesos | F17: Compra Contado Continuo | G17: 9245 | H17: BONO TESORO NA | I17: BONO TESORO NACIONAL 30/06/25 U$S CG - Dolar MEP (local) | J17: 200000 | K17: 1184 | L17: 1 | M17: 236800000 | N17: 0 | O17: 0 | P17: 236800000 | Q17: Visual | R17: Dolar MEP (local) | S17: Origen: Visual | Fecha: 30/5/2025 | Cod: 9245 | Op: Compra Contado Continuo | T17: 1184
A18: Futuros | B18: 45811 | C18: 3/6/2025 | D18: 62414 | E18: Pesos | F18: Futuro Venta | H18: DLR062025 | J18: -200 | K18: 1204.5 | L18: 1 | M18: 0 | N18: 0 | O18: -349786.8 | P18: -349786.8 | Q18: Visual | R18: =IF(ISERROR(VLOOKUP(G18,EspeciesVisual!C:Q,5,FALSE)),"",VLOOKUP(G18,EspeciesVisual!C:Q,5,FALSE)) | S18: Origen: Visual | Fecha: 3/6/2025 | Cod: None | Op: Futuro Venta | T18: 1204.5
A19: Títulos Públicos | B19: 45811 | C19: 4/6/2025 | D19: 62413 | E19: Pesos | F19: Compra Contado Continuo | G19: 9245 | H19: BONO TESORO NA | I19: BONO TESORO NACIONAL 30/06/25 U$S CG - Dolar MEP (local) | J19: 200000 | K19: 1170 | L19: 1 | M19: 234000000 | N19: 0 | O19: 0 | P19: 234000000 | Q19: Visual | R19: Dolar MEP (local) | S19: Origen: Visual | Fecha: 3/6/2025 | Cod: 9245 | Op: Compra Contado Continuo | T19: 1170
A20: Títulos Públicos | B20: 45826 | C20: 18/6/2025 | D20: 68915 | E20: Pesos | F20: Venta Contado Continuo No | G20: 5921 | H20: BONO REP. ARGE | I20: BONO REP. ARGENTINA USD STEP UP 2030 - Dolar MEP (local) | J20: -146753 | K20: 781.1868 | L20: 1 | M20: -1.1464151e+08 | N20: 0 | O20: 0 | P20: -1.1464151e+08 | Q20: Visual | R20: Dolar MEP (local) | S20: Origen: Visual | Fecha: 18/6/2025 | Cod: 5921 | Op: Venta Contado Continuo No | T20: 781.1868
A21: Títulos Públicos | B21: 45826 | C21: 18/6/2025 | D21: 68914 | E21: Dolar ME | F21: Compra Contado Continuo | G21: 5921 | H21: BONO REP. ARGE | I21: BONO REP. ARGENTINA USD STEP UP 2030 - Dolar MEP (local) | J21: 146753 | K21: 0.6746 | L21: 1185 | M21: 98999.57 | N21: 0 | O21: 0 | P21: 98999.57 | Q21: Visual | R21: Dolar MEP (local) | S21: Origen: Visual | Fecha: 18/6/2025 | Cod: 5921 | Op: Compra Contado Continuo | T21: 0.6746
A22: Títulos Públicos | B22: 45827 | C22: 19/6/2025 | D22: 69553 | E22: Pesos | F22: Venta Contado Continuo No | G22: 5921 | H22: BONO REP. ARGE | I22: BONO REP. ARGENTINA USD STEP UP 2030 - Dolar MEP (local) | J22: -104790 | K22: 779.222 | L22: 1 | M22: -81654673 | N22: 0 | O22: 0 | P22: -81654673 | Q22: Visual | R22: Dolar MEP (local) | S22: Origen: Visual | Fecha: 19/6/2025 | Cod: 5921 | Op: Venta Contado Continuo No | T22: 779.222
A23: Títulos Públicos | B23: 45827 | C23: 19/6/2025 | D23: 69552 | E23: Dolar ME | F23: Compra Contado Continuo | G23: 5921 | H23: BONO REP. ARGE | I23: BONO REP. ARGENTINA USD STEP UP 2030 - Dolar MEP (local) | J23: 104790 | K23: 0.668 | L23: 1160 | M23: 69999.72 | N23: 0 | O23: 0 | P23: 69999.72 | Q23: Visual | R23: Dolar MEP (local) | S23: Origen: Visual | Fecha: 19/6/2025 | Cod: 5921 | Op: Compra Contado Continuo | T23: 0.668
A24: Futuros | B24: 45833 | C24: 25/6/2025 | D24: 72322 | E24: Pesos | F24: Futuro Compra | H24: DLR062025 | J24: 400 | K24: 1194.5 | L24: 1 | M24: 0 | N24: 0 | O24: 115627.6 | P24: 115627.6 | Q24: Visual | R24: =IF(ISERROR(VLOOKUP(G24,EspeciesVisual!C:Q,5,FALSE)),"",VLOOKUP(G24,EspeciesVisual!C:Q,5,FALSE)) | S24: Origen: Visual | Fecha: 25/6/2025 | Cod: None | Op: Futuro Compra | T24: 1194.5
A25: Títulos Públicos | B25: 45833 | C25: 26/6/2025 | D25: 72321 | E25: Pesos | F25: Venta Contado | G25: 9245 | H25: BONO TESORO NA | I25: BONO TESORO NACIONAL 30/06/25 U$S CG - Dolar MEP (local) | J25: -400000 | K25: 1171.4 | L25: 1 | M25: -4.6856e+08 | N25: 0 | O25: 0 | P25: -4.6856e+08 | Q25: Visual | R25: Dolar MEP (local) | S25: Origen: Visual | Fecha: 25/6/2025 | Cod: 9245 | Op: Venta Contado | T25: 1171.4
A26: Letras del Tesoro nac | B26: 45833 | C26: 25/6/2025 | D26: 71646 | E26: Pesos | F26: Venta Contado Continuo No | G26: 9336 | H26: LT REP ARG CAP | I26: LT REP ARG CAP V.10/07/25 $ CG - Pesos | J26: -117198824 | K26: 1.0043 | L26: 1 | M26: -1.1770278e+08 | N26: 0 | O26: 0 | P26: -1.1770278e+08 | Q26: Visual | R26: Pesos | S26: Origen: Visual | Fecha: 25/6/2025 | Cod: 9336 | Op: Venta Contado Continuo No | T26: 1.0043
A27: Letras del Tesoro nac | B27: 45833 | C27: 25/6/2025 | D27: 71645 | E27: Dolar ME | F27: Compra Contado Continuo | G27: 9336 | H27: LT REP ARG CAP | I27: LT REP ARG CAP V.10/07/25 $ CG - Pesos | J27: 117198824 | K27: 0.0009 | L27: 1195 | M27: 99619 | N27: 0 | O27: 0 | P27: 99619 | Q27: Visual | R27: Pesos | S27: Origen: Visual | Fecha: 25/6/2025 | Cod: 9336 | Op: Compra Contado Continuo | T27: 0.00085
A28: Títulos Públicos | B28: 45834 | C28: 27/6/2025 | D28: 72765 | E28: Pesos | F28: Venta Contado | G28: 5921 | H28: BONO REP. ARGE | I28: BONO REP. ARGENTINA USD STEP UP 2030 - Dolar MEP (local) | J28: -6480 | K28: 825.7 | L28: 1 | M28: -5350536 | N28: 0 | O28: -5885.59 | P28: -5344650.4 | Q28: Visual | R28: Dolar MEP (local) | S28: Origen: Visual | Fecha: 26/6/2025 | Cod: 5921 | Op: Venta Contado | T28: 825.7
A29: Títulos Públicos | B29: 45834 | C29: 27/6/2025 | D29: 72764 | E29: Dolar ME | F29: Compra Contado | G29: 5921 | H29: BONO REP. ARGE | I29: BONO REP. ARGENTINA USD STEP UP 2030 - Dolar MEP (local) | J29: 6480 | K29: 0.6915 | L29: 1205 | M29: 4480.92 | N29: 0 | O29: 0 | P29: 4481.37 | Q29: Visual | R29: Dolar MEP (local) | S29: Origen: Visual | Fecha: 26/6/2025 | Cod: 5921 | Op: Compra Contado | T29: 0.6915
A30: Títulos Públicos | B30: 45834 | C30: 27/6/2025 | D30: 72767 | E30: Dolar ME | F30: Venta Contado | G30: 9235 | H30: BOPREAL S. 1 B V | I30: BOPREAL S. 1 B VTO31/10/27 U$S CG - Dolar MEP (local) | J30: -224031 | K30: 0.984 | L30: 1205 | M30: -220446.5 | N30: 0 | O30: 0 | P30: -220204.01 | Q30: Visual | R30: Dolar MEP (local) | S30: Origen: Visual | Fecha: 26/6/2025 | Cod: 9235 | Op: Venta Contado | T30: 0.984
A31: Títulos Públicos | B31: 45834 | C31: 27/6/2025 | D31: 72766 | E31: Dolar ME | F31: Compra Contado | G31: 9235 | H31: BOPREAL S. 1 B V | I31: BOPREAL S. 1 B VTO31/10/27 U$S CG - Dolar MEP (local) | J31: 18207 | K31: 0.986 | L31: 1205 | M31: 17952.1 | N31: 0 | O31: 0 | P31: 17953.9 | Q31: Visual | R31: Dolar MEP (local) | S31: Origen: Visual | Fecha: 26/6/2025 | Cod: 9235 | Op: Compra Contado | T31: 0.986
A32: Letras del Tesoro nac | B32: 45838 | C32: 30/6/2025 | D32: 74097 | E32: Pesos | F32: Venta Contado Continuo No | G32: 9336 | H32: LT REP ARG CAP | I32: LT REP ARG CAP V.10/07/25 $ CG - Pesos | J32: -234899991 | K32: 1.0149 | L32: 1 | M32: -2.384e+08 | N32: 0 | O32: 0 | P32: -2.384e+08 | Q32: Visual | R32: Pesos | S32: Origen: Visual | Fecha: 30/6/2025 | Cod: 9336 | Op: Venta Contado Continuo No | T32: 1.0149
A33: Letras del Tesoro nac | B33: 45838 | C33: 30/6/2025 | D33: 74096 | E33: Dolar ME | F33: Compra Contado Continuo | G33: 9336 | H33: LT REP ARG CAP | I33: LT REP ARG CAP V.10/07/25 $ CG - Pesos | J33: 234899991 | K33: 0.0009 | L33: 1205 | M33: 199664.99 | N33: 0 | O33: 0 | P33: 199664.99 | Q33: Visual | R33: Pesos | S33: Origen: Visual | Fecha: 30/6/2025 | Cod: 9336 | Op: Compra Contado Continuo | T33: 0.00084999999
A34: Letras del Tesoro nac | B34: 45839 | C34: 1/7/2025 | D34: 75056 | E34: Pesos | F34: Venta Contado Continuo No | G34: 9336 | H34: LT REP ARG CAP | I34: LT REP ARG CAP V.10/07/25 $ CG - Pesos | J34: -297126301 | K34: 1.0147 | L34: 1 | M34: -3.0149406e+08 | N34: 0 | O34: 0 | P34: -3.0149406e+08 | Q34: Visual | R34: Pesos | S34: Origen: Visual | Fecha: 1/7/2025 | Cod: 9336 | Op: Venta Contado Continuo No | T34: 1.0147
A35: Letras del Tesoro nac | B35: 45839 | C35: 1/7/2025 | D35: 75055 | E35: Dolar ME | F35: Compra Contado Continuo | G35: 9336 | H35: LT REP ARG CAP | I35: LT REP ARG CAP V.10/07/25 $ CG - Pesos | J35: 297126301 | K35: 0.0008 | L35: 1215 | M35: 249586.09 | N35: 0 | O35: 0 | P35: 249586.09 | Q35: Visual | R35: Pesos | S35: Origen: Visual | Fecha: 1/7/2025 | Cod: 9336 | Op: Compra Contado Continuo | T35: 0.00083999999
A36: Letras del Tesoro nac | B36: 45840 | C36: 2/7/2025 | D36: 75897 | E36: Pesos | F36: Venta Contado Continuo No | G36: 9336 | H36: LT REP ARG CAP | I36: LT REP ARG CAP V.10/07/25 $ CG - Pesos | J36: -296896672 | K36: 1.0382 | L36: 1 | M36: -3.0823812e+08 | N36: 0 | O36: 0 | P36: -3.0823812e+08 | Q36: Visual | R36: Pesos | S36: Origen: Visual | Fecha: 2/7/2025 | Cod: 9336 | Op: Venta Contado Continuo No | T36: 1.0382
... A79: Títulos Públicos | B79: 45978 | C79: 18/11/2025 | D79: 154211 | E79: Dolar ME | F79: Venta Contado | G79: 5922 | H79: BONO REP. ARGE | I79: BONO REP. ARGENTINA USD STEP UP 2035 - Dolar MEP (local) | J79: -336800 | K79: 0.7487 | L79: 1425 | M79: -252162.33 | N79: 0 | O79: 0 | P79: -251758.87 | Q79: Visual | R79: Dolar MEP (local) | S79: Origen: Visual | Fecha: 17/11/2025 | Cod: 5922 | Op: Venta Contado | T79: 0.7487

Sheet Cauciones Tomadoras
A1: Concertación | B1: Plazo | C1: Liquidación | D1: Operación | E1: Boleto | F1: Contado | G1: Futuro | H1: Tipo de Cambio | I1: Tasa (%) | J1: Interés Bruto | K1: Interés Devengado | L1: Aranceles | M1: Derechos | N1: Costo Financiero | O1: Moneda | P1: Origen | Q1: Auditoría
A2: 45656 | B2: 3 | C2: 45659 | D2: TOM CAU TER | E2: 136043 | F2: -475346.98 | G2: -475377.84 | H2: 1167.806 | J2: -30.86 | K2: -30.86 | L2: -8.63 | M2: 0 | N2: -39.49 | O2: Dolar MEP | P2: Gallo-Cauciones Dolares | Q2: Origen: Gallo-Cauciones Dolares
A3: 45659 | B3: 1 | C3: 45660 | D3: TOM CAU TER | E3: 511 | F3: -475386.47 | G3: -475392.98 | H3: 1167.806 | J3: -6.51 | K3: -6.51 | L3: -2.88 | M3: 0 | N3: -9.39 | O3: Dolar MEP | P3: Gallo-Cauciones Dolares | Q3: Origen: Gallo-Cauciones Dolares
A4: 45660 | B4: 3 | C4: 45663 | D4: TOM CAU TER | E4: 1095 | F4: -475395.86 | G4: -475415.01 | H4: 1167.806 | J4: -19.15 | K4: -19.15 | L4: -8.63 | M4: 0 | N4: -27.78 | O4: Dolar MEP | P4: Gallo-Cauciones Dolares | Q4: Origen: Gallo-Cauciones Dolares
A5: 45663 | B5: 1 | C5: 45664 | D5: TOM CAU TER | E5: 1645 | F5: -475423.64 | G5: -475429.37 | H5: 1167.806 | J5: -5.73 | K5: -5.73 | L5: -2.88 | M5: 0 | N5: -8.61 | O5: Dolar MEP | P5: Gallo-Cauciones Dolares | Q5: Origen: Gallo-Cauciones Dolares
A6: 45664 | B6: 1 | C6: 45665 | D6: TOM CAU TER | E6: 2205 | F6: -475432.25 | G6: -475437.33 | H6: 1167.806 | J6: -5.08 | K6: -5.08 | L6: -2.88 | M6: 0 | N6: -7.96 | O6: Dolar MEP | P6: Gallo-Cauciones Dolares | Q6: Origen: Gallo-Cauciones Dolares
A7: 45665 | B7: 143 | C7: 45808 | D7: TOM CAU TER | E7: 2807 | F7: -475440.21 | G7: -475444.12 | H7: 1167.806 | J7: -3.91 | K7: -3.91 | L7: -2.88 | M7: 0 | N7: -6.79 | O7: Dolar MEP | P7: Gallo-Cauciones Dolares | Q7: Origen: Gallo-Cauciones Dolares
A8: 45666 | B8: 1 | C8: 45667 | D8: TOM CAU TER | E8: 3344 | F8: -475447 | G8: -475451.95 | H8: 1167.806 | J8: -4.95 | K8: -4.95 | L8: -2.88 | M8: 0 | N8: -7.83 | O8: Dolar MEP | P8: Gallo-Cauciones Dolares | Q8: Origen: Gallo-Cauciones Dolares
A9: 45667 | B9: 3 | C9: 45670 | D9: TOM CAU TER | E9: 4024 | F9: -475454.83 | G9: -475462.26 | H9: 1167.806 | J9: -7.43 | K9: -7.43 | L9: -200.4 | M9: 0 | N9: -207.83 | O9: Dolar MEP | P9: Gallo-Cauciones Dolares | Q9: Origen: Gallo-Cauciones Dolares
A10: 45670 | B10: 1 | C10: 45671 | D10: TOM CAU TER | E10: 4696 | F10: -475662.66 | G10: -475667.09 | H10: 1167.806 | J10: -4.43 | K10: -4.43 | L10: -66.83 | M10: 0 | N10: -71.26 | O10: Dolar MEP | P10: Gallo-Cauciones Dolares | Q10: Origen: Gallo-Cauciones Dolares
A11: 45671 | B11: 1 | C11: 45672 | D11: TOM CAU TER | E11: 5480 | F11: -475733.92 | G11: -475738.61 | H11: 1167.806 | J11: -4.69 | K11: -4.69 | L11: -66.84 | M11: 0 | N11: -71.53 | O11: Dolar MEP | P11: Gallo-Cauciones Dolares | Q11: Origen: Gallo-Cauciones Dolares
A12: 45672 | B12: 1 | C12: 45673 | D12: TOM CAU TER | E12: 6212 | F12: -475805.45 | G12: -475811.19 | H12: 1167.806 | J12: -5.74 | K12: -5.74 | L12: -66.85 | M12: 0 | N12: -72.59 | O12: Dolar MEP | P12: Gallo-Cauciones Dolares | Q12: Origen: Gallo-Cauciones Dolares
A13: 45673 | B13: 1 | C13: 45674 | D13: TOM CAU TER | E13: 6786 | F13: -475878 | G13: -475882.57 | H13: 1167.806 | J13: -4.57 | K13: -4.57 | L13: -66.86 | M13: 0 | N13: -71.43 | O13: Dolar MEP | P13: Gallo-Cauciones Dolares | Q13: Origen: Gallo-Cauciones Dolares
... A74: 45771 | B74: 1 | C74: 45772 | D74: TOM CAU TER | E74: 46609 | F74: -60055.74 | G74: -60059.67 | H74: 1167.806 | J74: -3.93 | K74: -3.93 | L74: -30.6 | M74: 0 | N74: -34.53 | O74: Dolar MEP | P74: Gallo-Cauciones Dolares | Q74: Origen: Gallo-Cauciones Dolares
A75: 45810 | B75: 1 | C75: 45811 | D75: Apertura Tomador Cauci | E75: 62888 | F75: 3300000 | G75: 3302133.7 | H75: 1 | I75: 23.6 | J75: -2133.7 | K75: -2133.7 | L75: -218.94 | M75: -19.98 | N75: -2372.62 | O75: Pesos | P75: Visual-Cauciones Tomadoras | Q75: Origen: Visual-Cauciones Tomadoras
A76: 45810 | B76: 1 | C76: 45811 | D76: Apertura Tomador Cauci | E76: 62888 | F76: 1088000 | G76: 1088703.5 | H76: 1 | I76: 23.6 | J76: -703.47 | K76: -703.47 | L76: -72.18 | M76: -6.59 | N76: -782.24 | O76: Pesos | P76: Visual-Cauciones Tomadoras | Q76: Origen: Visual-Cauciones Tomadoras
A77: 45810 | B77: 1 | C77: 45811 | D77: Apertura Tomador Cauci | E77: 62888 | F77: 72549.35 | G77: 72596.26 | H77: 1 | I77: 23.6 | J77: -46.91 | K77: -46.91 | L77: -4.81 | M77: -0.44 | N77: -52.16 | O77: Pesos | P77: Visual-Cauciones Tomadoras | Q77: Origen: Visual-Cauciones Tomadoras
A78: 45810 | B78: 1 | C78: 45811 | D78: Apertura Tomador Cauci | E78: 62888 | F78: 68000 | G78: 68043.97 | H78: 1 | I78: 23.6 | J78: -43.97 | K78: -43.97 | L78: -4.51 | M78: -0.41 | N78: -48.89 | O78: Pesos | P78: Visual-Cauciones Tomadoras | Q78: Origen: Visual-Cauciones Tomadoras
A79: 45810 | B79: 1 | C79: 45811 | D79: Apertura Tomador Cauci | E79: 62888 | F79: 23016.96 | G79: 23031.84 | H79: 1 | I79: 23.6 | J79: -14.88 | K79: -14.88 | L79: -1.53 | M79: -0.14 | N79: -16.55 | O79: Pesos | P79: Visual-Cauciones Tomadoras | Q79: Origen: Visual-Cauciones Tomadoras
A80: 45810 | B80: 1 | C80: 45811 | D80: Apertura Tomador Cauci | E80: 62888 | F80: 500000 | G80: 500323.29 | H80: 1 | I80: 23.6 | J80: -323.29 | K80: -323.29 | L80: -33.17 | M80: -3.03 | N80: -359.49 | O80: Pesos | P80: Visual-Cauciones Tomadoras | Q80: Origen: Visual-Cauciones Tomadoras
A81: 45810 | B81: 1 | C81: 45811 | D81: Apertura Tomador Cauci | E81: 62888 | F81: 23478585 | G81: 23493766 | H81: 1 | I81: 23.6 | J81: -15180.67 | K81: -15180.67 | L81: -1557.67 | M81: -142.14 | N81: -16880.48 | O81: Pesos | P81: Visual-Cauciones Tomadoras | Q81: Origen: Visual-Cauciones Tomadoras
A82: 45810 | B82: 1 | C82: 45811 | D82: Apertura Tomador Cauci | E82: 62888 | F82: 5000000 | G82: 5003232.9 | H82: 1 | I82: 23.6 | J82: -3232.88 | K82: -3232.88 | L82: -331.72 | M82: -30.27 | N82: -3594.87 | O82: Pesos | P82: Visual-Cauciones Tomadoras | Q82: Origen: Visual-Cauciones Tomadoras
A83: 45810 | B83: 1 | C83: 45811 | D83: Apertura Tomador Cauci | E83: 62888 | F83: 1.3238925e+08 | G83: 1.3247485e+08 | H83: 1 | I83: 23.6 | J83: -85599.63 | K83: -85599.63 | L83: -8783.26 | M83: -801.47 | N83: -95184.36 | O83: Pesos | P83: Visual-Cauciones Tomadoras | Q83: Origen: Visual-Cauciones Tomadoras
A84: 45810 | B84: 1 | C84: 45811 | D84: Apertura Tomador Cauci | E84: 62888 | F84: 60292775 | G84: 60331759 | H84: 1 | I84: 23.6 | J84: -38983.82 | K84: -38983.82 | L84: -4000.08 | M84: -365.01 | N84: -43348.91 | O84: Pesos | P84: Visual-Cauciones Tomadoras | Q84: Origen: Visual-Cauciones Tomadoras
A85: 45810 | B85: 1 | C85: 45811 | D85: Apertura Tomador Cauci | E85: 62888 | F85: 1007026.4 | G85: 1007677.5 | H85: 1 | I85: 23.6 | J85: -651.12 | K85: -651.12 | L85: -66.81 | M85: -6.1 | N85: -724.03 | O85: Pesos | P85: Visual-Cauciones Tomadoras | Q85: Origen: Visual-Cauciones Tomadoras
A86: 45810 | B86: 1 | C86: 45811 | D86: Apertura Tomador Cauci | E86: 62888 | F86: 3488772.7 | G86: 3491028.5 | H86: 1 | I86: 23.6 | J86: -2255.75 | K86: -2255.75 | L86: -231.46 | M86: -21.12 | N86: -2508.33 | O86: Pesos | P86: Visual-Cauciones Tomadoras | Q86: Origen: Visual-Cauciones Tomadoras
... A195: 45834 | B195: 1 | C195: 45835 | D195: Apertura Tomador Cauci | E195: 72990 | F195: 28.48 | G195: -3753.56 | H195: 1 | I195: 0 | J195: 0 | K195: 0 | L195: 0 | M195: 0 | N195: 0 | O195: Pesos | P195: Visual-Cauciones Tomadoras | Q195: Origen: Visual-Cauciones Tomadoras

Sheet Cauciones Colocadoras
A1: Concertación | B1: Plazo | C1: Liquidación | D1: Operación | E1: Boleto | F1: Contado | G1: Futuro | H1: Tipo de Cambio | I1: Tasa (%) | J1: Interés Bruto | K1: Interés Devengado | L1: Aranceles | M1: Derechos | N1: Costo Financiero | O1: Moneda | P1: Origen | Q1: Auditoría

Sheet Rentas y Dividendos Gallo
A1: Tipo de Instrumento | B1: Concertación | C1: Liquidación | D1: Nro. Boleto | E1: Moneda | F1: Tipo Operación | G1: Cod.Instrum | H1: Instrumento Crudo | I1: InstrumentoConMoneda | J1: Cantidad | K1: Precio | L1: Tipo Cambio | M1: Bruto | N1: Interés | O1: Gastos | P1: Costo | Q1: Neto Calculado | R1: Origen | S1: moneda emision | T1: Auditoría

Sheet Resultado Ventas ARS
A1: Origen | B1: Tipo de Instrumento | C1: Instrumento | D1: Cod.Instrum | E1: Concertación | F1: Liquidación | G1: Moneda | H1: Tipo Operación | I1: Cantidad | J1: Precio | K1: Bruto | L1: Interés | M1: Tipo de Cambio | N1: Gastos | O1: IVA | P1: Resultado | Q1: Cantidad Stock Inicial | R1: Precio Stock Inicial | S1: Costo por venta(gallo) | T1: Neto Calculado(visual) | U1: Resultado Calculado(final) | V1: Cantidad de Stock Final | W1: Precio Stock Final | X1: Explicación Q | Y1: Explicación R-U | Z1: chequeado | AA1: Precio Nominal
A2: gallo-Renta Fija Pesos | B2: Títulos Públicos | C2: LT REP ARGENTINA CAP $ V31/03/25 - Pesos | D2: 9256 | E2: 45733 | G2: Pesos | H2: COMPRA | I2: 16000000 | J2: 156 | K2: 24960000 | L2: 0 | M2: 1 | N2: 0 | O2: 0 | Q2: 0 | R2: 0 | S2: 0 | T2: 24960000 | U2: 0 | V2: 16000000 | W2: 1.56 | X2: BUSCARV(D2→Posicion Inicial Gallo col V=Precio Nominal, fallback PrecioTenenciasIniciales/PreciosInicialesEspecies) | Y2: R=Precio stock previo | S=16000000*R2=16000000*[stock price] | T=K2+L2=2496000000.0+0 | U=|T2|-|S2| | Z2: Origen: gallo-Renta Fija Pesos | Cod: 9256 | AA2: 1.56
A3: gallo-Renta Fija Pesos | B3: Títulos Públicos | C3: LT REP ARGENTINA CAP $ V31/03/25 - Pesos | D3: 9256 | E3: 45734 | G3: Pesos | H3: VENTA | I3: -16000000 | J3: 136.031 | K3: -21764960 | L3: 0 | M3: 1 | N3: 0 | O3: 0 | Q3: 16000000 | R3: 1.56 | S3: -24960000 | T3: -21764960 | U3: -3195040 | V3: 0 | W3: 0 | X3: SI D3=D2: W2, SINO: BUSCARV(D3→Posicion Inicial Gallo col V=Precio Nominal, fallback PrecioTenenciasIniciales/PreciosInicialesEspecies) | Y3: R=Precio stock previo | S=-16000000*R3=-16000000*[stock price] | T=K3+L3=-2176496000.0+0 | U=|T3|-|S3| | Z3: Origen: gallo-Renta Fija Pesos | Cod: 9256 | AA3: 1.36031
A4: gallo-Renta Fija Pesos | B4: Títulos Públicos | C4: BONO TESORO NACION AJ CER V30/5/25 $ CG - Pesos | D4: 9311 | E4: 45784 | G4: Pesos | H4: COMPRA | I4: 90867961 | J4: 122.982 | K4: 1.1175124e+08 | L4: 0 | M4: 1 | N4: 0 | O4: 0 | Q4: 0 | R4: 0 | S4: 0 | T4: 1.1175124e+08 | U4: 0 | V4: 90867961 | W4: 1.22982 | X4: SI D4=D3: W3, SINO: BUSCARV(D4→Posicion Inicial Gallo col V=Precio Nominal, fallback PrecioTenenciasIniciales/PreciosInicialesEspecies) | Y4: R=Precio stock previo | S=90867961*R4=90867961*[stock price] | T=K4+L4=11175123579.702+0 | U=|T4|-|S4| | Z4: Origen: gallo-Renta Fija Pesos | Cod: 9311 | AA4: 1.22982
A5: gallo-Renta Fija Pesos | B5: Títulos Públicos | C5: BONO TESORO NACION AJ CER V30/5/25 $ CG - Pesos | D5: 9311 | E5: 45784 | G5: Pesos | H5: VENTA | I5: -90867961 | J5: 118.244 | K5: -1.0744591e+08 | L5: 0 | M5: 1 | N5: 0 | O5: 0 | Q5: 90867961 | R5: 1.22982 | S5: -1.1175124e+08 | T5: -1.0744591e+08 | U5: -4305324 | V5: 0 | W5: 0 | X5: SI D5=D4: W4, SINO: BUSCARV(D5→Posicion Inicial Gallo col V=Precio Nominal, fallback PrecioTenenciasIniciales/PreciosInicialesEspecies) | Y5: R=Precio stock previo | S=-90867961*R5=-90867961*[stock price] | T=K5+L5=-10744591180.484+0 | U=|T5|-|S5| | Z5: Origen: gallo-Renta Fija Pesos | Cod: 9311 | AA5: 1.18244

Sheet Resultado Ventas USD
A1: Origen | B1: Tipo de Instrumento | C1: Instrumento | D1: Cod.Instrum | E1: Concertación | F1: Liquidación | G1: Moneda | H1: Tipo Operación | I1: Cantidad | J1: Precio | K1: Precio Standarizado | L1: Precio Standarizado en USD | M1: Bruto en USD | N1: Interés | O1: Tipo de Cambio | P1: Valor USD Dia | Q1: Gastos USD | R1: IVA USD | S1: Resultado | T1: Cantidad Stock Inicial | U1: Precio Stock USD | V1: Costo por venta(gallo) | W1: Neto Calculado(visual) | X1: Resultado Calculado(final) | Y1: Cantidad de Stock Final | Z1: Precio Stock Final | AA1: Explicación T-Z | AB1: Auditoría | AC1: Precio Nominal
A2: gallo-Renta Fija Dolares | B2: Títulos Públicos | C2: BONO REP. ARGENTINA USD STEP UP 2030 - Dolar MEP (local) | D2: 5921 | E2: 45768 | G2: Dolar MEP | H2: COMPRA | I2: 150056 | J2: 64.692 | K2: 64.692 | L2: 64.692 | M2: 97074.228 | N2: 0 | O2: 1 | P2: 1122.08 | Q2: 0 | R2: 0 | T2: 0 | U2: 0.76005775 | V2: 0 | W2: 97074.228 | X2: 0 | Y2: 150056 | Z2: 0.64692 | AA2: T=BUSCARV(D2→Posicion Inicial Gallo col V=Precio Nominal, fallback PrecioTenenciasIniciales/PreciosInicialesEspecies) | U=PrecioPos/P2 | V=150056*U si venta | Q=GastosUSD | W=M +/- Q segun signo | X=|W|-|V| | Y=I+T | Z=Promedio | AB2: Origen: gallo-Renta Fija Dolares | Cod: 5921 | K(PrecioStd)=raw | L=K*O | GastosFuente=0 | AC2: 0.64692
A3: gallo-Renta Fija Dolares | B3: Títulos Públicos | C3: BONO REP. ARGENTINA USD STEP UP 2030 - Dolar MEP (local) | D3: 5921 | E3: 45768 | G3: Dolar MEP | H3: VENTA USD | I3: -150056 | J3: 66.479 | K3: 66.479 | L3: 66.479 | M3: -99755.728 | N3: 0 | O3: 1 | P3: 1122.08 | Q3: 0 | R3: 0 | T3: 150056 | U3: 0.64692 | V3: -97074.228 | W3: -99755.728 | X3: 2681.5007 | Y3: 0 | Z3: 0 | AA3: SI D3=D2: Z2, SINO: BUSCARV(col V=Precio Nominal (Posicion Inicial Gallo), fallback PrecioTenenciasIniciales/PreciosInicialesEspecies) | U=PrecioPos/P3 | V=-150056*U si venta | Q=GastosUSD | W=M +/- Q segun signo | X=|W|-|V| | Y=I+T | Z=Promedio | AB3: Origen: gallo-Renta Fija Dolares | Cod: 5921 | K(PrecioStd)=raw | L=K*O | GastosFuente=0 | AC3: 0.66479
A4: gallo-Renta Fija Dolares | B4: Títulos Públicos | C4: BONO REP. ARGENTINA USD STEP UP 2030 - Dolar MEP (local) | D4: 5921 | E4: 45796 | G4: Dolar MEP | H4: COMPRA | I4: 140242 | J4: 67.74 | K4: 67.74 | L4: 67.74 | M4: 94999.931 | N4: 0 | O4: 1 | P4: 1148.77 | Q4: 0 | R4: 0 | T4: 0 | U4: 0.64692 | V4: 0 | W4: 94999.931 | X4: 0 | Y4: 140242 | Z4: 0.6774 | AA4: SI D4=D3: Z3, SINO: BUSCARV(col V=Precio Nominal (Posicion Inicial Gallo), fallback PrecioTenenciasIniciales/PreciosInicialesEspecies) | U=PrecioPos/P4 | V=140242*U si venta | Q=GastosUSD | W=M +/- Q segun signo | X=|W|-|V| | Y=I+T | Z=Promedio | AB4: Origen: gallo-Renta Fija Dolares | Cod: 5921 | K(PrecioStd)=raw | L=K*O | GastosFuente=0 | AC4: 0.6774
A5: gallo-Renta Fija Dolares | B5: Títulos Públicos | C5: BONO REP. ARGENTINA USD STEP UP 2030 - Dolar MEP (local) | D5: 5921 | E5: 45796 | G5: Dolar MEP | H5: VENTA | I5: -140242 | J5: 66.727 | K5: 66.727 | L5: 66.727 | M5: -93579.279 | N5: 0 | O5: 1 | P5: 1148.77 | Q5: 0 | R5: 0 | T5: 140242 | U5: 0.6774 | V5: -94999.931 | W5: -93579.279 | X5: -1420.6515 | Y5: 0 | Z5: 0 | AA5: SI D5=D4: Z4, SINO: BUSCARV(col V=Precio Nominal (Posicion Inicial Gallo), fallback PrecioTenenciasIniciales/PreciosInicialesEspecies) | U=PrecioPos/P5 | V=-140242*U si venta | Q=GastosUSD | W=M +/- Q segun signo | X=|W|-|V| | Y=I+T | Z=Promedio | AB5: Origen: gallo-Renta Fija Dolares | Cod: 5921 | K(PrecioStd)=raw | L=K*O | GastosFuente=0 | AC5: 0.66727
A6: gallo-Renta Fija Dolares | B6: Títulos Públicos | C6: BONO REP. ARGENTINA USD STEP UP 2030 - Dolar MEP (local) | D6: 5921 | E6: 45799 | G6: Dolar MEP | H6: COMPRA | I6: 144117 | J6: 68 | K6: 68 | L6: 68 | M6: 97999.56 | N6: 0 | O6: 1 | P6: 1143.49 | Q6: 0 | R6: 0 | T6: 0 | U6: 0.6774 | V6: 0 | W6: 97999.56 | X6: 0 | Y6: 144117 | Z6: 0.68 | AA6: SI D6=D5: Z5, SINO: BUSCARV(col V=Precio Nominal (Posicion Inicial Gallo), fallback PrecioTenenciasIniciales/PreciosInicialesEspecies) | U=PrecioPos/P6 | V=144117*U si venta | Q=GastosUSD | W=M +/- Q segun signo | X=|W|-|V| | Y=I+T | Z=Promedio | AB6: Origen: gallo-Renta Fija Dolares | Cod: 5921 | K(PrecioStd)=raw | L=K*O | GastosFuente=0 | AC6: 0.68
A7: gallo-Renta Fija Dolares | B7: Títulos Públicos | C7: BONO REP. ARGENTINA USD STEP UP 2030 - Dolar MEP (local) | D7: 5921 | E7: 45799 | G7: Dolar MEP | H7: VENTA | I7: -144117 | J7: 67.854 | K7: 67.854 | L7: 67.854 | M7: -97789.149 | N7: 0 | O7: 1 | P7: 1143.49 | Q7: 0 | R7: 0 | T7: 144117 | U7: 0.68 | V7: -97999.56 | W7: -97789.149 | X7: -210.41082 | Y7: 0 | Z7: 0 | AA7: SI D7=D6: Z6, SINO: BUSCARV(col V=Precio Nominal (Posicion Inicial Gallo), fallback PrecioTenenciasIniciales/PreciosInicialesEspecies) | U=PrecioPos/P7 | V=-144117*U si venta | Q=GastosUSD | W=M +/- Q segun signo | X=|W|-|V| | Y=I+T | Z=Promedio | AB7: Origen: gallo-Renta Fija Dolares | Cod: 5921 | K(PrecioStd)=raw | L=K*O | GastosFuente=0 | AC7: 0.67854
A8: Visual | B8: Títulos Públicos | C8: BONO REP. ARGENTINA USD STEP UP 2030 - Dolar MEP (local) | D8: 5921 | E8: 45826 | F8: 18/6/2025 | G8: Dolar ME | H8: Compra Contado Continuo | I8: 146753 | J8: 0.6746 | K8: 67.46 | L8: 67.46 | M8: 98999.574 | N8: 0 | O8: 1 | P8: 1185 | Q8: 0 | R8: 0 | T8: 0 | U8: 0.68 | V8: 0 | W8: 98999.574 | X8: 0 | Y8: 146753 | Z8: 0.6746 | AA8: SI D8=D7: Z7, SINO: BUSCARV(col V=Precio Nominal (Posicion Inicial Gallo), fallback PrecioTenenciasIniciales/PreciosInicialesEspecies) | U=PrecioPos/P8 | V=146753*U si venta | Q=GastosUSD | W=M +/- Q segun signo | X=|W|-|V| | Y=I+T | Z=Promedio | AB8: Origen: Visual | Cod: 5921 | K(PrecioStd)=x100 | L=K*O | GastosFuente=0 | AC8: 0.6746
A9: Visual | B9: Títulos Públicos | C9: BONO REP. ARGENTINA USD STEP UP 2030 - Dolar MEP (local) | D9: 5921 | E9: 45826 | F9: 18/6/2025 | G9: Pesos | H9: Venta Contado Continuo No | I9: -146753 | J9: 781.1868 | K9: 78118.68 | L9: 65.922937 | M9: -96743.887 | N9: 0 | O9: 0.00084388186 | P9: 1185 | Q9: 0 | R9: 0 | T9: 146753 | U9: 0.6746 | V9: -98999.574 | W9: -96743.887 | X9: -2255.6865 | Y9: 0 | Z9: 0 | AA9: SI D9=D8: Z8, SINO: BUSCARV(col V=Precio Nominal (Posicion Inicial Gallo), fallback PrecioTenenciasIniciales/PreciosInicialesEspecies) | U=PrecioPos/P9 | V=-146753*U si venta | Q=GastosUSD | W=M +/- Q segun signo | X=|W|-|V| | Y=I+T | Z=Promedio | AB9: Origen: Visual | Cod: 5921 | K(PrecioStd)=x100 | L=K*O | GastosFuente=0 | AC9: 0.65922937
A10: Visual | B10: Títulos Públicos | C10: BONO REP. ARGENTINA USD STEP UP 2030 - Dolar MEP (local) | D10: 5921 | E10: 45827 | F10: 19/6/2025 | G10: Dolar ME | H10: Compra Contado Continuo | I10: 104790 | J10: 0.668 | K10: 66.8 | L10: 66.8 | M10: 69999.72 | N10: 0 | O10: 1 | P10: 1160 | Q10: 0 | R10: 0 | T10: 0 | U10: 0.6746 | V10: 0 | W10: 69999.72 | X10: 0 | Y10: 104790 | Z10: 0.668 | AA10: SI D10=D9: Z9, SINO: BUSCARV(col V=Precio Nominal (Posicion Inicial Gallo), fallback PrecioTenenciasIniciales/PreciosInicialesEspecies) | U=PrecioPos/P10 | V=104790*U si venta | Q=GastosUSD | W=M +/- Q segun signo | X=|W|-|V| | Y=I+T | Z=Promedio | AB10: Origen: Visual | Cod: 5921 | K(PrecioStd)=x100 | L=K*O | GastosFuente=0 | AC10: 0.668
A11: Visual | B11: Títulos Públicos | C11: BONO REP. ARGENTINA USD STEP UP 2030 - Dolar MEP (local) | D11: 5921 | E11: 45827 | F11: 19/6/2025 | G11: Pesos | H11: Venta Contado Continuo No | I11: -104790 | J11: 779.222 | K11: 77922.2 | L11: 67.17431 | M11: -70391.96 | N11: 0 | O11: 0.00086206897 | P11: 1160 | Q11: 0 | R11: 0 | T11: 104790 | U11: 0.668 | V11: -69999.72 | W11: -70391.96 | X11: 392.23981 | Y11: 0 | Z11: 0 | AA11: SI D11=D10: Z10, SINO: BUSCARV(col V=Precio Nominal (Posicion Inicial Gallo), fallback PrecioTenenciasIniciales/PreciosInicialesEspecies) | U=PrecioPos/P11 | V=-104790*U si venta | Q=GastosUSD | W=M +/- Q segun signo | X=|W|-|V| | Y=I+T | Z=Promedio | AB11: Origen: Visual | Cod: 5921 | K(PrecioStd)=x100 | L=K*O | GastosFuente=0 | AC11: 0.6717431
A12: Visual | B12: Títulos Públicos | C12: BONO REP. ARGENTINA USD STEP UP 2030 - Dolar MEP (local) | D12: 5921 | E12: 45834 | F12: 27/6/2025 | G12: Dolar ME | H12: Compra Contado | I12: 6480 | J12: 0.6915 | K12: 69.15 | L12: 69.15 | M12: 4480.92 | N12: 0 | O12: 1 | P12: 1205 | Q12: 0 | R12: 0 | T12: 0 | U12: 0.668 | V12: 0 | W12: 4480.92 | X12: 0 | Y12: 6480 | Z12: 0.6915 | AA12: SI D12=D11: Z11, SINO: BUSCARV(col V=Precio Nominal (Posicion Inicial Gallo), fallback PrecioTenenciasIniciales/PreciosInicialesEspecies) | U=PrecioPos/P12 | V=6480*U si venta | Q=GastosUSD | W=M +/- Q segun signo | X=|W|-|V| | Y=I+T | Z=Promedio | AB12: Origen: Visual | Cod: 5921 | K(PrecioStd)=x100 | L=K*O | GastosFuente=0 | AC12: 0.6915
A13: Visual | B13: Títulos Públicos | C13: BONO REP. ARGENTINA USD STEP UP 2030 - Dolar MEP (local) | D13: 5921 | E13: 45834 | F13: 27/6/2025 | G13: Pesos | H13: Venta Contado | I13: -6480 | J13: 825.7 | K13: 82570 | L13: 68.522822 | M13: -4440.2788 | N13: 0 | O13: 0.00082987552 | P13: 1205 | Q13: 0 | R13: 0 | T13: 6480 | U13: 0.6915 | V13: -4480.92 | W13: -4440.2788 | X13: -40.641162 | Y13: 0 | Z13: 0 | AA13: SI D13=D12: Z12, SINO: BUSCARV(col V=Precio Nominal (Posicion Inicial Gallo), fallback PrecioTenenciasIniciales/PreciosInicialesEspecies) | U=PrecioPos/P13 | V=-6480*U si venta | Q=GastosUSD | W=M +/- Q segun signo | X=|W|-|V| | Y=I+T | Z=Promedio | AB13: Origen: Visual | Cod: 5921 | K(PrecioStd)=x100 | L=K*O | GastosFuente=-5885.59 | AC13: 0.68522822
A14: Visual | B14: Títulos Públicos | C14: BONO REP. ARGENTINA USD STEP UP 2030 - Dolar MEP (local) | D14: 5921 | E14: 45849 | F14: 11/7/2025 | G14: Dolar ME | H14: Compra Contado | I14: 938 | J14: 0.5998 | K14: 59.98 | L14: 59.98 | M14: 562.6124 | N14: 0 | O14: 1 | P14: 1275 | Q14: 0 | R14: 0 | T14: 0 | U14: 0.6915 | V14: 0 | W14: 562.6124 | X14: 0 | Y14: 938 | Z14: 0.5998 | AA14: SI D14=D13: Z13, SINO: BUSCARV(col V=Precio Nominal (Posicion Inicial Gallo), fallback PrecioTenenciasIniciales/PreciosInicialesEspecies) | U=PrecioPos/P14 | V=938*U si venta | Q=GastosUSD | W=M +/- Q segun signo | X=|W|-|V| | Y=I+T | Z=Promedio | AB14: Origen: Visual | Cod: 5921 | K(PrecioStd)=x100 | L=K*O | GastosFuente=0 | AC14: 0.5998
A15: Visual | B15: Títulos Públicos | C15: BONO REP. ARGENTINA USD STEP UP 2030 - Dolar MEP (local) | D15: 5921 | E15: 45849 | F15: 11/7/2025 | G15: Pesos | H15: Venta Contado | I15: -938 | J15: 760.2 | K15: 76020 | L15: 59.623529 | M15: -559.26871 | N15: 0 | O15: 0.00078431373 | P15: 1275 | Q15: 0 | R15: 0 | T15: 938 | U15: 0.5998 | V15: -562.6124 | W15: -559.26871 | X15: -3.3436941 | Y15: 0 | Z15: 0 | AA15: SI D15=D14: Z14, SINO: BUSCARV(col V=Precio Nominal (Posicion Inicial Gallo), fallback PrecioTenenciasIniciales/PreciosInicialesEspecies) | U=PrecioPos/P15 | V=-938*U si venta | Q=GastosUSD | W=M +/- Q segun signo | X=|W|-|V| | Y=I+T | Z=Promedio | AB15: Origen: Visual | Cod: 5921 | K(PrecioStd)=x100 | L=K*O | GastosFuente=-784.38 | AC15: 0.59623529
A16: Visual | B16: Títulos Públicos | C16: BONO REP. ARGENTINA USD STEP UP 2030 - Dolar MEP (local) | D16: 5921 | E16: 45854 | F16: 16/7/2025 | G16: Dolar ME | H16: Compra Contado Continuo | I16: 333979 | J16: 0.5967 | K16: 59.67 | L16: 59.67 | M16: 199285.27 | N16: 0 | O16: 1 | P16: 1280 | Q16: 0 | R16: 0 | T16: 0 | U16: 0.5998 | V16: 0 | W16: 199285.27 | X16: 0 | Y16: 333979 | Z16: 0.5967 | AA16: SI D16=D15: Z15, SINO: BUSCARV(col V=Precio Nominal (Posicion Inicial Gallo), fallback PrecioTenenciasIniciales/PreciosInicialesEspecies) | U=PrecioPos/P16 | V=333979*U si venta | Q=GastosUSD | W=M +/- Q segun signo | X=|W|-|V| | Y=I+T | Z=Promedio | AB16: Origen: Visual | Cod: 5921 | K(PrecioStd)=x100 | L=K*O | GastosFuente=0 | AC16: 0.5967
A17: Visual | B17: Títulos Públicos | C17: BONO REP. ARGENTINA USD STEP UP 2030 - Dolar MEP (local) | D17: 5921 | E17: 45854 | F17: 16/7/2025 | G17: Pesos | H17: Venta Contado Continuo No | I17: -333979 | J17: 751.2453 | K17: 75124.53 | L17: 58.691039 | M17: -196015.75 | N17: 0 | O17: 0.00078125 | P17: 1280 | Q17: 0 | R17: 0 | T17: 333979 | U17: 0.5967 | V17: -199285.27 | W17: -196015.75 | X17: -3269.5239 | Y17: 0 | Z17: 0 | AA17: SI D17=D16: Z16, SINO: BUSCARV(col V=Precio Nominal (Posicion Inicial Gallo), fallback PrecioTenenciasIniciales/PreciosInicialesEspecies) | U=PrecioPos/P17 | V=-333979*U si venta | Q=GastosUSD | W=M +/- Q segun signo | X=|W|-|V| | Y=I+T | Z=Promedio | AB17: Origen: Visual | Cod: 5921 | K(PrecioStd)=x100 | L=K*O | GastosFuente=0 | AC17: 0.58691039
A18: Visual | B18: Títulos Públicos | C18: BONO REP. ARGENTINA USD STEP UP 2030 - Dolar MEP (local) | D18: 5921 | E18: 45898 | F18: 29/8/2025 | G18: Dolar ME | H18: Compra Contado Continuo | I18: 506230 | J18: 0.5912 | K18: 59.12 | L18: 59.12 | M18: 299283.18 | N18: 0 | O18: 1 | P18: 1345 | Q18: 0 | R18: 0 | T18: 0 | U18: 0.5967 | V18: 0 | W18: 299283.18 | X18: 0 | Y18: 506230 | Z18: 0.5912 | AA18: SI D18=D17: Z17, SINO: BUSCARV(col V=Precio Nominal (Posicion Inicial Gallo), fallback PrecioTenenciasIniciales/PreciosInicialesEspecies) | U=PrecioPos/P18 | V=506230*U si venta | Q=GastosUSD | W=M +/- Q segun signo | X=|W|-|V| | Y=I+T | Z=Promedio | AB18: Origen: Visual | Cod: 5921 | K(PrecioStd)=x100 | L=K*O | GastosFuente=0 | AC18: 0.5912
A19: Visual | B19: Títulos Públicos | C19: BONO REP. ARGENTINA USD STEP UP 2030 - Dolar MEP (local) | D19: 5921 | E19: 45898 | F19: 29/8/2025 | G19: Pesos | H19: Venta Contado Continuo No | I19: -506230 | J19: 788.003 | K19: 78800.3 | L19: 58.587584 | M19: -296587.92 | N19: 0 | O19: 0.00074349442 | P19: 1345 | Q19: 0 | R19: 0 | T19: 506230 | U19: 0.5912 | V19: -299283.18 | W19: -296587.92 | X19: -2695.2513 | Y19: 0 | Z19: 0 | AA19: SI D19=D18: Z18, SINO: BUSCARV(col V=Precio Nominal (Posicion Inicial Gallo), fallback PrecioTenenciasIniciales/PreciosInicialesEspecies) | U=PrecioPos/P19 | V=-506230*U si venta | Q=GastosUSD | W=M +/- Q segun signo | X=|W|-|V| | Y=I+T | Z=Promedio | AB19: Origen: Visual | Cod: 5921 | K(PrecioStd)=x100 | L=K*O | GastosFuente=0 | AC19: 0.58587584
... A30: Visual | B30: Títulos Públicos | C30: BONOS REP. ARG. U$S STEP UP V.09/07/35 - Dolar Cable (exterior) | D30: 81088 | E30: 45908 | F30: 8/9/2025 | G30: Pesos | H30: Venta Contado Continuo No | I30: -523368 | J30: 813.96 | K30: 81396 | L30: 58.982609 | M30: -308696.1 | N30: 0 | O30: 0.00072463768 | P30: 1380 | Q30: 0 | R30: 0 | T30: 523368 | U30: 0.57 | V30: -298319.76 | W30: -308696.1 | X30: 10376.339 | Y30: 0 | Z30: 0 | AA30: SI D30=D29: Z29, SINO: BUSCARV(col V=Precio Nominal (Posicion Inicial Gallo), fallback PrecioTenenciasIniciales/PreciosInicialesEspecies) | U=PrecioPos/P30 | V=-523368*U si venta | Q=GastosUSD | W=M +/- Q segun signo | X=|W|-|V| | Y=I+T | Z=Promedio | AB30: Origen: Visual | Cod: 81088 | K(PrecioStd)=x100 | L=K*O | GastosFuente=0 | AC30: 0.58982609
A31: gallo-Renta Fija Dolares | B31: Títulos Públicos | C31: BOPREAL S. 1 A VTO31/10/27 U$S CG - Dolar MEP (local) | D31: 9234 | E31: 45769 | G31: Dolar MEP | H31: VENTA USD | I31: -200000 | J31: 100 | K31: 100 | L31: 100 | M31: -200000 | N31: 0 | O31: 1 | P31: 1140.38 | Q31: 0 | R31: 0 | T31: 613798 | U31: 0.87822747 | V31: -175645.49 | W31: -200000 | X31: 24354.505 | Y31: 413798 | Z31: 0.87822747 | AA31: SI D31=D30: Z30, SINO: BUSCARV(col V=Precio Nominal (Posicion Inicial Gallo), fallback PrecioTenenciasIniciales/PreciosInicialesEspecies) | U=PrecioPos/P31 | V=-200000*U si venta | Q=GastosUSD | W=M +/- Q segun signo | X=|W|-|V| | Y=I+T | Z=Promedio | AB31: Origen: gallo-Renta Fija Dolares | Cod: 9234 | K(PrecioStd)=raw | L=K*O | GastosFuente=0 | AC31: 1
A32: gallo-Renta Fija Dolares | B32: Títulos Públicos | C32: BOPREAL S. 1 A VTO31/10/27 U$S CG - Dolar MEP (local) | D32: 9234 | E32: 45769 | G32: Dolar MEP | H32: VENTA | I32: -100000 | J32: 95.799 | K32: 95.799 | L32: 95.799 | M32: -95799 | N32: 0 | O32: 1 | P32: 1140.38 | Q32: 0 | R32: 0 | T32: 413798 | U32: 0.87822747 | V32: -87822.747 | W32: -95799 | X32: 7976.2525 | Y32: 313798 | Z32: 0.87822747 | AA32: SI D32=D31: Z31, SINO: BUSCARV(col V=Precio Nominal (Posicion Inicial Gallo), fallback PrecioTenenciasIniciales/PreciosInicialesEspecies) | U=PrecioPos/P32 | V=-100000*U si venta | Q=GastosUSD | W=M +/- Q segun signo | X=|W|-|V| | Y=I+T | Z=Promedio | AB32: Origen: gallo-Renta Fija Dolares | Cod: 9234 | K(PrecioStd)=raw | L=K*O | GastosFuente=0 | AC32: 0.95799
A33: gallo-Renta Fija Dolares | B33: Títulos Públicos | C33: BOPREAL S. 1 A VTO31/10/27 U$S CG - Dolar MEP (local) | D33: 9234 | E33: 45770 | G33: Dolar MEP | H33: VENTA USD | I33: -16458 | J33: 100 | K33: 100 | L33: 100 | M33: -16458 | N33: 0 | O33: 1 | P33: 1168 | Q33: 0 | R33: 0 | T33: 313798 | U33: 0.87822747 | V33: -14453.868 | W33: -16458 | X33: 2004.1322 | Y33: 297340 | Z33: 0.87822747 | AA33: SI D33=D32: Z32, SINO: BUSCARV(col V=Precio Nominal (Posicion Inicial Gallo), fallback PrecioTenenciasIniciales/PreciosInicialesEspecies) | U=PrecioPos/P33 | V=-16458*U si venta | Q=GastosUSD | W=M +/- Q segun signo | X=|W|-|V| | Y=I+T | Z=Promedio | AB33: Origen: gallo-Renta Fija Dolares | Cod: 9234 | K(PrecioStd)=raw | L=K*O | GastosFuente=0 | AC33: 1
A34: gallo-Renta Fija Dolares | B34: Títulos Públicos | C34: BOPREAL S. 1 A VTO31/10/27 U$S CG - Dolar MEP (local) | D34: 9234 | E34: 45771 | G34: Dolar MEP | H34: VENTA USD | I34: -85547 | J34: 100.012 | K34: 100.012 | L34: 100.012 | M34: -85557.266 | N34: 0 | O34: 1 | P34: 1186.53 | Q34: 0 | R34: 0 | T34: 297340 | U34: 0.87822747 | V34: -75129.726 | W34: -85557.266 | X34: 10427.54 | Y34: 211793 | Z34: 0.87822747 | AA34: SI D34=D33: Z33, SINO: BUSCARV(col V=Precio Nominal (Posicion Inicial Gallo), fallback PrecioTenenciasIniciales/PreciosInicialesEspecies) | U=PrecioPos/P34 | V=-85547*U si venta | Q=GastosUSD | W=M +/- Q segun signo | X=|W|-|V| | Y=I+T | Z=Promedio | AB34: Origen: gallo-Renta Fija Dolares | Cod: 9234 | K(PrecioStd)=raw | L=K*O | GastosFuente=0 | AC34: 1.00012
A35: gallo-Renta Fija Dolares | B35: Títulos Públicos | C35: BOPREAL S. 1 A VTO31/10/27 U$S CG - Dolar MEP (local) | D35: 9234 | E35: 45772 | G35: Dolar MEP | H35: VENTA USD | I35: -211793 | J35: 100.25 | K35: 100.25 | L35: 100.25 | M35: -212322.48 | N35: 0 | O35: 1 | P35: 1184.24 | Q35: 0 | R35: 0 | T35: 211793 | U35: 0.87822747 | V35: -186002.43 | W35: -212322.48 | X35: 26320.051 | Y35: 0 | Z35: 0 | AA35: SI D35=D34: Z34, SINO: BUSCARV(col V=Precio Nominal (Posicion Inicial Gallo), fallback PrecioTenenciasIniciales/PreciosInicialesEspecies) | U=PrecioPos/P35 | V=-211793*U si venta | Q=GastosUSD | W=M +/- Q segun signo | X=|W|-|V| | Y=I+T | Z=Promedio | AB35: Origen: gallo-Renta Fija Dolares | Cod: 9234 | K(PrecioStd)=raw | L=K*O | GastosFuente=0 | AC35: 1.0025
A36: Visual | B36: Títulos Públicos | C36: BOPREAL S. 1 B VTO31/10/27 U$S CG - Dolar MEP (local) | D36: 9235 | E36: 45834 | F36: 27/6/2025 | G36: Dolar ME | H36: Compra Contado | I36: 18207 | J36: 0.986 | K36: 98.6 | L36: 98.6 | M36: 17952.102 | N36: 0 | O36: 1 | P36: 1205 | Q36: 0 | R36: 0 | T36: 0 | U36: 0.90691433 | V36: 0 | W36: 17952.102 | X36: 0 | Y36: 18207 | Z36: 0.986 | AA36: SI D36=D35: Z35, SINO: BUSCARV(col V=Precio Nominal (Posicion Inicial Gallo), fallback PrecioTenenciasIniciales/PreciosInicialesEspecies) | U=PrecioPos/P36 | V=18207*U si venta | Q=GastosUSD | W=M +/- Q segun signo | X=|W|-|V| | Y=I+T | Z=Promedio | AB36: Origen: Visual | Cod: 9235 | K(PrecioStd)=x100 | L=K*O | GastosFuente=0 | AC36: 0.986
A37: Visual | B37: Títulos Públicos | C37: BOPREAL S. 1 B VTO31/10/27 U$S CG - Dolar MEP (local) | D37: 9235 | E37: 45834 | F37: 27/6/2025 | G37: Dolar ME | H37: Venta Contado | I37: -224031 | J37: 0.984 | K37: 98.4 | L37: 98.4 | M37: -220446.5 | N37: 0 | O37: 1 | P37: 1205 | Q37: 0 | R37: 0 | T37: 18207 | U37: 0.986 | V37: -220894.57 | W37: -220446.5 | X37: -448.062 | Y37: -205824 | Z37: 0.986 | AA37: SI D37=D36: Z36, SINO: BUSCARV(col V=Precio Nominal (Posicion Inicial Gallo), fallback PrecioTenenciasIniciales/PreciosInicialesEspecies) | U=PrecioPos/P37 | V=-224031*U si venta | Q=GastosUSD | W=M +/- Q segun signo | X=|W|-|V| | Y=I+T | Z=Promedio | AB37: Origen: Visual | Cod: 9235 | K(PrecioStd)=x100 | L=K*O | GastosFuente=0 | AC37: 0.984
A38: Visual | B38: Títulos Públicos | C38: BONO TESORO NACIONAL 30/06/25 U$S CG - Dolar MEP (local) | D38: 9245 | E38: 45807 | F38: 2/6/2025 | G38: Pesos | H38: Compra Contado Continuo | I38: 200000 | J38: 1184 | K38: 118400 | L38: 99.352197 | M38: 198704.39 | N38: 0 | O38: 0.00083912328 | P38: 1191.72 | Q38: 0 | R38: 0 | T38: 0 | U38: 0.88798996 | V38: 0 | W38: 198704.39 | X38: 0 | Y38: 200000 | Z38: 0.99352197 | AA38: SI D38=D37: Z37, SINO: BUSCARV(col V=Precio Nominal (Posicion Inicial Gallo), fallback PrecioTenenciasIniciales/PreciosInicialesEspecies) | U=PrecioPos/P38 | V=200000*U si venta | Q=GastosUSD | W=M +/- Q segun signo | X=|W|-|V| | Y=I+T | Z=Promedio | AB38: Origen: Visual | Cod: 9245 | K(PrecioStd)=x100 | L=K*O | GastosFuente=0 | AC38: 0.99352197
A39: Visual | B39: Títulos Públicos | C39: BONO TESORO NACIONAL 30/06/25 U$S CG - Dolar MEP (local) | D39: 9245 | E39: 45811 | F39: 4/6/2025 | G39: Pesos | H39: Compra Contado Continuo | I39: 200000 | J39: 1170 | K39: 117000 | L39: 98.3466 | M39: 196693.2 | N39: 0 | O39: 0.00084056923 | P39: 1189.67 | Q39: 0 | R39: 0 | T39: 200000 | U39: 0.99352197 | V39: 0 | W39: 196693.2 | X39: 0 | Y39: 400000 | Z39: 0.98849399 | AA39: SI D39=D38: Z38, SINO: BUSCARV(col V=Precio Nominal (Posicion Inicial Gallo), fallback PrecioTenenciasIniciales/PreciosInicialesEspecies) | U=PrecioPos/P39 | V=200000*U si venta | Q=GastosUSD | W=M +/- Q segun signo | X=|W|-|V| | Y=I+T | Z=Promedio | AB39: Origen: Visual | Cod: 9245 | K(PrecioStd)=x100 | L=K*O | GastosFuente=0 | AC39: 0.983466
A40: Visual | B40: Títulos Públicos | C40: BONO TESORO NACIONAL 30/06/25 U$S CG - Dolar MEP (local) | D40: 9245 | E40: 45833 | F40: 26/6/2025 | G40: Pesos | H40: Venta Contado | I40: -400000 | J40: 1171.4 | K40: 117140 | L40: 97.907943 | M40: -391631.77 | N40: 0 | O40: 0.0008358199 | P40: 1196.43 | Q40: 0 | R40: 0 | T40: 400000 | U40: 0.98849399 | V40: -395397.59 | W40: -391631.77 | X40: -3765.8231 | Y40: 0 | Z40: 0 | AA40: SI D40=D39: Z39, SINO: BUSCARV(col V=Precio Nominal (Posicion Inicial Gallo), fallback PrecioTenenciasIniciales/PreciosInicialesEspecies) | U=PrecioPos/P40 | V=-400000*U si venta | Q=GastosUSD | W=M +/- Q segun signo | X=|W|-|V| | Y=I+T | Z=Promedio | AB40: Origen: Visual | Cod: 9245 | K(PrecioStd)=x100 | L=K*O | GastosFuente=0 | AC40: 0.97907943
A41: Visual | B41: Títulos Públicos | C41: BONTES $ A DESC AJ CER V15/12/27 - Pesos | D41: 9250 | E41: 45909 | F41: 9/9/2025 | G41: Dolar ME | H41: Compra Contado Continuo | I41: 274408787 | J41: 0.0011 | K41: 0.0011 | L41: 0.0011 | M41: 301849.67 | N41: 0 | O41: 1 | P41: 1425 | Q41: 0 | R41: 0 | T41: 0 | U41: 0.0012330815 | V41: 0 | W41: 301849.67 | X41: 0 | Y41: 274408787 | Z41: 0.0011 | AA41: SI D41=D40: Z40, SINO: BUSCARV(col V=Precio Nominal (Posicion Inicial Gallo), fallback PrecioTenenciasIniciales/PreciosInicialesEspecies) | U=PrecioPos/P41 | V=274408787*U si venta | Q=GastosUSD | W=M +/- Q segun signo | X=|W|-|V| | Y=I+T | Z=Promedio | AB41: Origen: Visual | Cod: 9250 | K(PrecioStd)=raw | L=K*O | GastosFuente=0 | AC41: 0.0011
A42: Visual | B42: Títulos Públicos | C42: BONTES $ A DESC AJ CER V15/12/27 - Pesos | D42: 9250 | E42: 45909 | F42: 9/9/2025 | G42: Pesos | H42: Venta Contado Continuo No | I42: -274408787 | J42: 1.5538 | K42: 1.5538 | L42: 0.001090386 | M42: -299211.49 | N42: 0 | O42: 0.00070175439 | P42: 1425 | Q42: 0 | R42: 0 | T42: 274408787 | U42: 0.0011 | V42: -301849.67 | W42: -299211.49 | X42: -2638.1757 | Y42: 0 | Z42: 0 | AA42: SI D42=D41: Z41, SINO: BUSCARV(col V=Precio Nominal (Posicion Inicial Gallo), fallback PrecioTenenciasIniciales/PreciosInicialesEspecies) | U=PrecioPos/P42 | V=-274408787*U si venta | Q=GastosUSD | W=M +/- Q segun signo | X=|W|-|V| | Y=I+T | Z=Promedio | AB42: Origen: Visual | Cod: 9250 | K(PrecioStd)=raw | L=K*O | GastosFuente=0 | AC42: 0.001090386
A43: Visual | B43: Letras del Tesoro nac | C43: LETRAS DEL TESORO CAP $ V31/07/25 - Pesos | D43: 9305 | E43: 45848 | F43: 10/7/2025 | G43: Dolar ME | H43: Compra Contado Continuo | I43: 218804409 | J43: 0.0011 | K43: 0.0011 | L43: 0.0011 | M43: 249437.03 | N43: 0 | O43: 1 | P43: 1275 | Q43: 0 | R43: 0 | T43: 0 | U43: 0.0010838701 | V43: 0 | W43: 249437.03 | X43: 0 | Y43: 218804409 | Z43: 0.00114 | AA43: SI D43=D42: Z42, SINO: BUSCARV(col V=Precio Nominal (Posicion Inicial Gallo), fallback PrecioTenenciasIniciales/PreciosInicialesEspecies) | U=PrecioPos/P43 | V=218804409*U si venta | Q=GastosUSD | W=M +/- Q segun signo | X=|W|-|V| | Y=I+T | Z=Promedio | AB43: Origen: Visual | Cod: 9305 | K(PrecioStd)=raw | L=K*O | GastosFuente=0 | AC43: 0.0011
A44: Visual | B44: Letras del Tesoro nac | C44: LETRAS DEL TESORO CAP $ V31/07/25 - Pesos | D44: 9305 | E44: 45848 | F44: 10/7/2025 | G44: Pesos | H44: Venta Contado Continuo No | I44: -218804409 | J44: 1.4428 | K44: 1.4428 | L44: 0.0011316078 | M44: -247600.79 | N44: 0 | O44: 0.00078431373 | P44: 1275 | Q44: 0 | R44: 0 | T44: 218804409 | U44: 0.00114 | V44: -249437.03 | W44: -247600.79 | X44: -1836.2447 | Y44: 0 | Z44: 0 | AA44: SI D44=D43: Z43, SINO: BUSCARV(col V=Precio Nominal (Posicion Inicial Gallo), fallback PrecioTenenciasIniciales/PreciosInicialesEspecies) | U=PrecioPos/P44 | V=-218804409*U si venta | Q=GastosUSD | W=M +/- Q segun signo | X=|W|-|V| | Y=I+T | Z=Promedio | AB44: Origen: Visual | Cod: 9305 | K(PrecioStd)=raw | L=K*O | GastosFuente=0 | AC44: 0.0011316078
A45: Visual | B45: Letras del Tesoro nac | C45: LETRAS DEL TESORO CAP $ V31/07/25 - Pesos | D45: 9305 | E45: 45849 | F45: 11/7/2025 | G45: Dolar ME | H45: Compra Contado Continuo | I45: 216790302 | J45: 0.0012 | K45: 0.0012 | L45: 0.0012 | M45: 249308.85 | N45: 0 | O45: 1 | P45: 1275 | Q45: 0 | R45: 0 | T45: 0 | U45: 0.00114 | V45: 0 | W45: 249308.85 | X45: 0 | Y45: 216790302 | Z45: 0.00115 | AA45: SI D45=D44: Z44, SINO: BUSCARV(col V=Precio Nominal (Posicion Inicial Gallo), fallback PrecioTenenciasIniciales/PreciosInicialesEspecies) | U=PrecioPos/P45 | V=216790302*U si venta | Q=GastosUSD | W=M +/- Q segun signo | X=|W|-|V| | Y=I+T | Z=Promedio | AB45: Origen: Visual | Cod: 9305 | K(PrecioStd)=raw | L=K*O | GastosFuente=0 | AC45: 0.0012
A46: Visual | B46: Letras del Tesoro nac | C46: LETRAS DEL TESORO CAP $ V31/07/25 - Pesos | D46: 9305 | E46: 45849 | F46: 11/7/2025 | G46: Pesos | H46: Venta Contado Continuo No | I46: -216790302 | J46: 1.4559 | K46: 1.4559 | L46: 0.0011418824 | M46: -247549.02 | N46: 0 | O46: 0.00078431373 | P46: 1275 | Q46: 0 | R46: 0 | T46: 216790302 | U46: 0.00115 | V46: -249308.85 | W46: -247549.02 | X46: -1759.8299 | Y46: 0 | Z46: 0 | AA46: SI D46=D45: Z45, SINO: BUSCARV(col V=Precio Nominal (Posicion Inicial Gallo), fallback PrecioTenenciasIniciales/PreciosInicialesEspecies) | U=PrecioPos/P46 | V=-216790302*U si venta | Q=GastosUSD | W=M +/- Q segun signo | X=|W|-|V| | Y=I+T | Z=Promedio | AB46: Origen: Visual | Cod: 9305 | K(PrecioStd)=raw | L=K*O | GastosFuente=0 | AC46: 0.0011418824
A47: Visual | B47: Letras del Tesoro nac | C47: LETRAS DEL TESORO CAP $ V31/07/25 - Pesos | D47: 9305 | E47: 45852 | F47: 14/7/2025 | G47: Dolar ME | H47: Compra Contado Continuo | I47: 216766273 | J47: 0.0012 | K47: 0.0012 | L47: 0.0012 | M47: 249281.21 | N47: 0 | O47: 1 | P47: 1275 | Q47: 0 | R47: 0 | T47: 0 | U47: 0.00115 | V47: 0 | W47: 249281.21 | X47: 0 | Y47: 216766273 | Z47: 0.00115 | AA47: SI D47=D46: Z46, SINO: BUSCARV(col V=Precio Nominal (Posicion Inicial Gallo), fallback PrecioTenenciasIniciales/PreciosInicialesEspecies) | U=PrecioPos/P47 | V=216766273*U si venta | Q=GastosUSD | W=M +/- Q segun signo | X=|W|-|V| | Y=I+T | Z=Promedio | AB47: Origen: Visual | Cod: 9305 | K(PrecioStd)=raw | L=K*O | GastosFuente=0 | AC47: 0.0012
... A73: Visual | B73: Títulos Públicos | C73: BOPREAL 4B VTO31/10/28 U$S CG - Dolar MEP (local) | D73: 9350 | E73: 45973 | F73: 13/11/2025 | G73: Dolar ME | H73: Compra Contado | I73: 307000 | J73: 0.815 | K73: 81.5 | L73: 81.5 | M73: 250205 | N73: 0 | O73: 1 | P73: 1440 | Q73: 0 | R73: 0 | T73: 0 | U73: 0 | V73: 0 | W73: 250205 | X73: 0 | Y73: 307000 | Z73: 0.815 | AA73: SI D73=D72: Z72, SINO: BUSCARV(col V=Precio Nominal (Posicion Inicial Gallo), fallback PrecioTenenciasIniciales/PreciosInicialesEspecies) | U=PrecioPos/P73 | V=307000*U si venta | Q=GastosUSD | W=M +/- Q segun signo | X=|W|-|V| | Y=I+T | Z=Promedio | AB73: Origen: Visual | Cod: 9350 | K(PrecioStd)=x100 | L=K*O | GastosFuente=0 | AC73: 0.815

Sheet Rentas Dividendos ARS
A1: Instrumento | B1: Cod.Instrum | C1: Categoría | D1: tipo_instrumento | E1: Concertación | F1: Liquidación | G1: Nro. NDC | H1: Tipo Operación | I1: Cantidad | J1: Moneda | K1: Tipo de Cambio | L1: Gastos | M1: Importe | N1: Origen | O1: Importe Original

Sheet Rentas Dividendos USD
A1: Instrumento | B1: Cod.Instrum | C1: Categoría | D1: tipo_instrumento | E1: Concertación | F1: Liquidación | G1: Nro. NDC | H1: Tipo Operación | I1: Cantidad | J1: Moneda | K1: Tipo de Cambio | L1: Gastos | M1: Importe | N1: Origen | O1: Importe Original

Sheet FCI
A1: Concertación | B1: Liquidación | C1: Moneda | D1: Tipo Operación | E1: Cantidad | F1: Tipo de Cambio | G1: Precio | H1: Bruto | I1: Gastos | J1: IVA | K1: Resultado

Sheet Opciones
A1: Instrumento | B1: Concertación | C1: Liquidación | D1: Moneda | E1: Tipo Operación | F1: Cantidad | G1: Tipo de Cambio | H1: Precio | I1: Bruto | J1: Gastos | K1: IVA | L1: Resultado

Sheet Futuros
A1: Moneda | B1: Instrumento | C1: Tipo de Liquidación | D1: Total
A2: ARS | B2: DLR062025 - Pesos | C2: MTM - Diferencia | D2: -1900000
A3: ARS | B3: DLR062025 - Pesos | C3: Resultado - Cancelación | D3: 6600000

Sheet Pagare_CPD
A1: Instrumento | B1: Concertación | C1: Liquidación | D1: Vencimiento | E1: Tipo Operación | F1: Abreviatura | G1: Moneda | H1: Tipo Cambio | I1: Valor Nominal | J1: Tasa | K1: Valor Final | L1: Gastos | M1: Neto | N1: Origen

Sheet Resumen
A1: Moneda | B1: Ventas | C1: FCI | D1: Opciones | E1: Rentas | F1: Dividendos | G1: Pagare/CPD | H1: Futuros | I1: Cau (Tom) | J1: Cau (Col) | K1: Total
A2: ARS | B2: -7500364 | C2: 0 | D2: 0 | E2: 0 | F2: 0 | G2: 0 | H2: 4700000 | I2: -8540413.2 | J2: 0 | K2: -11340777
A3: USD | B3: 40519.464 | C3: 0 | D3: 0 | E3: 0 | F3: 0 | G3: 0 | H3: 0 | I3: -6715.46 | J3: 0 | K3: 33804.004

Sheet Posicion Titulos
A1: Instrumento | B1: Código | C1: Ticker | D1: Cantidad | E1: Importe | F1: Moneda | G1: Origen
