Workbook

Sheet Posicion Inicial Gallo
A1: tipo_especie | B1: Ticker | C1: especie | D1: Codigo especie | E1: Codigo Especie Origen | F1: comentario especies | G1: detalle | H1: custodia | I1: cantidad | J1: precio Tenencia Inicial Pesos | K1: precio Tenencia Inicial USD | L1: Precio de PreciosIniciales | M1: precio costo(en proceso) | N1: Origen precio costo | O1: comentarios precio costo | P1: Precio a Utilizar | Q1: importe_pesos | R1: porc_cartera_pesos | S1: importe_dolares | T1: porc_cartera_dolares | U1: Tipo Instrumento | V1: Precio Nominal
A2: RENTA FIJA EN PESOS | B2: T13F6 | C2: BONO TESORO NACI CAP V.13/02/26 $ CG | D2: 9314 | E2: PreciosInicialesEspecies | H2: CAJA VALORES | I2: 95498084 | J2: 1.0755 | K2: 0.00092095816 | L2: 109.4 | N2: PrecioTenenciasIniciales | P2: 1.04661 | Q2: 1.0270819e+08 | R2: 44.36 | S2: 87949.74 | T2: 44.36 | U2: Títulos Públicos | V2: 1.04661
A3: RENTA FIJA EN PESOS | B3: GNCXO | C3: ON GENNEIA SA REGS 8,75% V.02/09/2027 | D3: 81993 | E3: PreciosInicialesEspecies | H3: CAJA VALORES | I3: 15000 | J3: 753.8 | K3: 0.645484 | L3: 74000 | N3: PrecioTenenciasIniciales | P3: 676.25038 | Q3: 11307000 | R3: 4.88 | S3: 9682.26 | T3: 4.88 | U3: Obligaciones Negociables | V3: 676.25038
A4: RENTA FIJA EN DOLARES | B4: BPOA7 | C4: BOPREAL S. 1 A VTO31/10/27 U$S CG | D4: 9234 | E4: PreciosInicialesEspecies | H4: CAJA VALORES | I4: 208333 | J4: 112460 | K4: 0.96300284 | L4: 112100 | N4: PrecioTenenciasIniciales | P4: 969.12 | Q4: 2.3429129e+08 | R4: 101.2 | S4: 200625.27 | T4: 101.2 | U4: Títulos Públicos | V4: 969.12
A5: RENTA FIJA EN DOLARES | B5: BPY26 | C5: BOPREAL S.3 VTO31/05/26 U$S CG | D5: 9247 | E5: PreciosInicialesEspecies | H5: CAJA VALORES | I5: 10400 | J5: 110900 | K5: 0.94964423 | L5: 109500 | N5: PrecioTenenciasIniciales | P5: 708.51975 | Q5: 11533600 | R5: 4.98 | S5: 9876.3 | T5: 4.98 | U5: Títulos Públicos | V5: 708.51975
A6: RENTA FIJA EN DOLARES | B6: CO26 | C6: TD PUB. PCIA. CORDOBA V.27/10/26 | D6: 32804 | E6: PreciosInicialesEspecies | H6: CAJA VALORES | I6: 9000 | J6: 31990 | K6: 0.27393222 | L6: 30560 | N6: PrecioTenenciasIniciales | P6: 24.918281 | Q6: 2879100 | R6: 1.24 | S6: 2465.39 | T6: 1.24 | U6: Títulos Públicos | V6: 24.918281
A7: RENTA FIJA EN DOLARES | B7: GD30 | C7: BONOS REP. ARG. U$S STEP UP V.09/07/30 | D7: 81086 | E7: PreciosInicialesEspecies | H7: CAJA VALORES | I7: 1500 | J7: 88870 | K7: 0.761 | L7: 89390 | N7: PrecioTenenciasIniciales | P7: 386.61676 | Q7: 1333050 | R7: 0.58 | S7: 1141.5 | T7: 0.58 | U7: Títulos Públicos | V7: 386.61676
A8: RENTA FIJA EN DOLARES | B8: GD35 | C8: BONOS REP. ARG. U$S STEP UP V.09/07/35 | D8: 81088 | E8: PreciosInicialesEspecies | H8: CAJA VALORES | I8: 211200 | J8: 81800 | K8: 0.70045909 | L8: 82400 | N8: PrecioTenenciasIniciales | P8: 566.73652 | Q8: 172761600 | R8: 74.62 | S8: 147936.96 | T8: 74.62 | U8: Títulos Públicos | V8: 566.73652
A9: RENTA FIJA EN DOLARES | B9: TLCMO-A | C9: TELECOM ARGENT 144A 9.5% VTO. 18/07/31 | D9: 83849 | E9: PreciosInicialesEspecies | H9: CAJA VALORES | I9: 10000 | J9: 128910 | K9: 1.103865 | L9: 127400 | N9: PrecioTenenciasIniciales | P9: 1289.1 | Q9: 12891000 | R9: 5.57 | S9: 11038.65 | T9: 5.57 | U9: Obligaciones Negociables | V9: 1289.1
A10: RENTA FIJA EN DOLARES | B10: YM | C10: CXO YPF SOCIEDAD ON 8.75% VTO. 11/09/31 | D10: 83928 | E10: EspeciesGallo | H10: CAJA VALORES | I10: 12140 | J10: 126550 | K10: 1.0836565 | L10: 0 | N10: PrecioTenenciasIniciales | P10: 997.16728 | Q10: 15363170 | R10: 6.64 | S10: 13155.59 | T10: 6.64 | U10: Obligaciones Negociables | V10: 997.16728
A11: CASH | B11: PESOS | C11: PESOS | G11: Cuenta Corriente | I11: -1.0030203e+08 | J11: 1 | K11: 0.00085630694 | L11: 1 | N11: PreciosInicialesEspecies | P11: 1 | Q11: -1.0030203e+08 | R11: -43.32 | S11: -85889.32 | T11: -43.32 | V11: 1
A12: CASH | B12: DOLARES | C12: DOLARES | G12: Cuenta Corriente | I12: -199853.89 | J12: 1167.8055 | K12: 1 | L12: 1167.806 | N12: PreciosInicialesEspecies | P12: 1167.806 | Q12: -2.3339048e+08 | R12: -100.81 | S12: -199853.89 | T12: -100.81 | V12: 1167.806
A13: CASH | B13: DOLAR | C13: DOLAR | G13: Cuenta Corriente | I13: 125.71 | J13: 1148.9303 | K13: 0.98385172 | L13: 1167.806 | N13: PreciosInicialesEspecies | P13: 1167.806 | Q13: 144432.03 | R13: 0.06 | S13: 123.68 | T13: 0.06 | V13: 1167.806

Sheet Posicion Final Gallo
A1: tipo_especie | B1: Ticker | C1: especie | D1: Codigo especie | E1: Codigo Especie Origen | F1: comentario especies | G1: detalle | H1: custodia | I1: cantidad | J1: precio Tenencia Final Pesos | K1: precio Tenencia Final USD | L1: Precio Tenencia Inicial | M1: precio costo(en proceso) | N1: Origen precio costo | O1: comentarios precio costo | P1: Precio a Utilizar | Q1: importe_pesos | R1: porc_cartera_pesos | S1: importe_dolares | T1: porc_cartera_dolares | U1: Tipo Instrumento | V1: Precio Nominal
A2: TITULOS PRIVADOS LOCALES | B2: ALUA | C2: ALUA ALUAR | D2: 7 | E2: PreciosInicialesEspecies | H2: CAJA VALORES | I2: 6150 | J2: 797 | K2: 0.66789919 | L2: 893 | N2: PreciosInicialesEspecies | P2: 893 | Q2: 4901550 | R2: 1.39 | S2: 4107.58 | T2: 1.39 | U2: Acciones | V2: 893
A3: TITULOS PRIVADOS LOCALES | B3: PAMP | C3: PAMPA HOLDING | D3: 457 | E3: PreciosInicialesEspecies | H3: CAJA VALORES | I3: 4350 | J3: 3700 | K3: 3.1006575 | L3: 4385 | N3: PreciosInicialesEspecies | P3: 4385 | Q3: 16095000 | R3: 4.55 | S3: 13487.86 | T3: 4.55 | U3: Acciones | V3: 4385
A4: TITULOS PRIVADOS LOCALES | B4: TGSU2 | C4: TGSU2 TRANSP. GAS DEL SUR | D4: 617 | E4: PreciosInicialesEspecies | H4: CAJA VALORES | I4: 2881 | J4: 6750 | K4: 5.6566053 | L4: 7690 | N4: PreciosInicialesEspecies | P4: 7690 | Q4: 19446750 | R4: 5.5 | S4: 16296.68 | T4: 5.5 | U4: Acciones | V4: 7690
A5: TITULOS PRIVADOS LOCALES | B5: HARG | C5: HARG HOLCIM ARGENTINA SA | D5: 733 | E5: PreciosInicialesEspecies | H5: CAJA VALORES | I5: 625 | J5: 1730 | K5: 1.44976 | L5: 2230 | N5: PreciosInicialesEspecies | P5: 2230 | Q5: 1081250 | R5: 0.31 | S5: 906.1 | T5: 0.31 | U5: Acciones | V5: 2230
A6: TITULOS PRIVADOS LOCALES | B6: TEN | C6: CEDEAR TENARIS S.A. (ADS) | D6: 8524 | E6: PreciosInicialesEspecies | H6: CAJA VALORES | I6: 83 | J6: 40400 | K6: 33.855783 | L6: 44300 | N6: PreciosInicialesEspecies | P6: 44300 | Q6: 3353200 | R6: 0.95 | S6: 2810.03 | T6: 0.95 | U6: Cedears | V6: 44300
A7: TITULOS PRIVADOS LOCALES | B7: LOMA | C7: LOMA NEGRA | D7: 30043 | E7: PreciosInicialesEspecies | H7: CAJA VALORES | I7: 950 | J7: 3045 | K7: 2.5517579 | L7: 2980 | N7: PreciosInicialesEspecies | P7: 2980 | Q7: 2892750 | R7: 0.82 | S7: 2424.17 | T7: 0.82 | U7: Acciones | V7: 2980
A8: RENTA FIJA EN PESOS | B8: VBC10 | C8: ON BCO DE VALORES CI. 1 V.11/03/2027 | D8: 58530 | E8: PreciosInicialesEspecies | H8: CAJA VALORES | I8: 8019 | J8: 1172 | K8: 0.98215364 | L8: 0 | N8: PreciosInicialesEspecies | P8: 0 | Q8: 9398268 | R8: 2.66 | S8: 7875.89 | T8: 2.66 | U8: Obligaciones Negociables | V8: 0
A9: RENTA FIJA EN PESOS | B9: GNCXO | C9: ON GENNEIA SA REGS 8,75% V.02/09/2027 | D9: 81993 | E9: PreciosInicialesEspecies | H9: CAJA VALORES | I9: 15000 | J9: 625 | K9: 0.52376 | L9: 74000 | N9: PreciosInicialesEspecies | P9: 74000 | Q9: 9375000 | R9: 2.65 | S9: 7856.4 | T9: 2.65 | U9: Obligaciones Negociables | V9: 740
A10: RENTA FIJA EN PESOS | B10: MGC90 | C10: ON PAMPA ENERGIA SA REGS 9.5% V08/12/26 | D10: 82445 | E10: PreciosInicialesEspecies | H10: CAJA VALORES | I10: 1333 | J10: 862.5 | K10: 0.7227907 | L10: 83970 | N10: PreciosInicialesEspecies | P10: 83970 | Q10: 1149712.5 | R10: 0.33 | S10: 963.48 | T10: 0.33 | U10: Obligaciones Negociables | V10: 839.7
A11: RENTA FIJA EN PESOS | B11: YMCHO | C11: ON YPF S.A. REGS 4% V.12/02/2026 | D11: 95610 | E11: PreciosInicialesEspecies | H11: CAJA VALORES | I11: 1917 | J11: 283 | K11: 0.23715702 | L11: 46340 | N11: PreciosInicialesEspecies | P11: 46340 | Q11: 542511 | R11: 0.15 | S11: 454.63 | T11: 0.15 | U11: Obligaciones Negociables | V11: 463.4
A12: RENTA FIJA EN DOLARES | B12: AL30 | C12: BONO USD 2030 LA | D12: 5921 | E12: PreciosInicialesEspecies | H12: CAJA VALORES | I12: 31373 | J12: 814.9 | K12: 0.68289899 | L12: 88760 | N12: PreciosInicialesEspecies | P12: 88760 | Q12: 25565858 | R12: 7.23 | S12: 21424.59 | T12: 7.23 | U12: Títulos Públicos | V12: 887.6
A13: RENTA FIJA EN DOLARES | B13: AL35 | C13: BONO USD 2035 LA | D13: 5922 | E13: PreciosInicialesEspecies | H13: CAJA VALORES | I13: 31373 | J13: 823.1 | K13: 0.6897705 | L13: 81630 | N13: PreciosInicialesEspecies | P13: 81630 | Q13: 25823116 | R13: 7.3 | S13: 21640.17 | T13: 7.3 | U13: Títulos Públicos | V13: 816.3
... A21: RENTA FIJA EN DOLARES | B21: YMCHO | C21: YPF SOCIEDAD ON 8.75% VTO. 11/09/31 | D21: 95610 | E21: PreciosInicialesEspecies | H21: CAJA VALORES | I21: 12140 | J21: 1269.9 | K21: 1.064196 | L21: 46340 | N21: PreciosInicialesEspecies | P21: 46340 | Q21: 15416586 | R21: 4.36 | S21: 12919.34 | T21: 4.36 | U21: Obligaciones Negociables | V21: 463.4
A22: CASH | B22: PESOS | C22: PESOS | G22: Cuenta Corriente | I22: 30465.07 | J22: 1 | K22: 0.00083800891 | L22: 1 | N22: PreciosInicialesEspecies | P22: 1 | Q22: 30465.07 | R22: 0.01 | S22: 25.53 | T22: 0.01 | V22: 1
A23: CASH | B23: DOLARES | C23: DOLARES | G23: Cuenta Corriente | I23: 2982.42 | J23: 1193.2953 | K23: 1 | L23: 1167.806 | N23: PreciosInicialesEspecies | P23: 1167.806 | Q23: 3558907.7 | R23: 1.01 | S23: 2982.42 | T23: 1.01 | V23: 1167.806
A24: CASH | B24: DOLAR | C24: DOLAR | G24: Cuenta Corriente | I24: 2531.67 | J24: 1179.6771 | K24: 0.98858856 | L24: 1167.806 | N24: PreciosInicialesEspecies | P24: 1167.806 | Q24: 2986553.1 | R24: 0.84 | S24: 2502.78 | T24: 0.84 | V24: 1167.806

Sheet Boletos
A1: Tipo de Instrumento | B1: Concertación | C1: Liquidación | D1: Nro. Boleto | E1: Moneda | F1: Tipo Operación | G1: Cod.Instrum | H1: Instrumento Crudo | I1: InstrumentoConMoneda | J1: Cantidad | K1: Precio | L1: Tipo Cambio | M1: Bruto | N1: Interés | O1: Gastos | P1: Neto Calculado | Q1: Origen | R1: moneda emision | S1: Auditoría | T1: Precio Nominal
A2: Títulos Públicos | B2: 45681 | D2: 9826 | E2: Pesos | F2: VENTA | G2: 9314 | H2: BONO TESORO NACI CAPV.13/02/26 $ CG | I2: BONO TESORO NACI CAP V.13/02/26 $ CG - Pesos | J2: -95498084 | K2: 109.3 | L2: 1 | M2: -1.0437941e+08 | N2: 0 | O2: 0 | P2: -1.0437941e+08 | Q2: gallo-Renta Fija Pesos | R2: Pesos | S2: Origen: Gallo-Renta Fija Pesos | Fecha: 24/01/25 | Cod: 09314 | Op: VENTA | T2: 1.093
A3: Títulos Públicos | B3: 45681 | D3: 10317 | E3: Dolar MEP | F3: CPRA CABLE | G3: 5921 | H3: BONO USD 2030 LA | I3: BONO REP. ARGENTINA USD STEP UP 2030 - Dolar MEP (local) | J3: 7631 | K3: 65.684 | L3: 1155.75 | M3: 5012.346 | N3: 0 | O3: 0 | P3: 5012.346 | Q3: gallo-Renta Fija Dolares | R3: Dolar MEP (local) | S3: Origen: Gallo-Renta Fija Dolares | Fecha: 24/01/25 | Cod: 05921 | Op: CPRA CABLE | T3: 0.65684
A4: Títulos Públicos | B4: 45681 | D4: 10318 | E4: Dolar MEP | F4: VENTA USD | G4: 5921 | H4: BONO USD 2030 LA | I4: BONO REP. ARGENTINA USD STEP UP 2030 - Dolar MEP (local) | J4: -7631 | K4: 60.935 | L4: 1155.75 | M4: -4649.9499 | N4: 0 | O4: 0 | P4: -4649.9499 | Q4: gallo-Renta Fija Dolares | R4: Dolar MEP (local) | S4: Origen: Gallo-Renta Fija Dolares | Fecha: 24/01/25 | Cod: 05921 | Op: VENTA USD | T4: 0.60935
A5: Títulos Públicos | B5: 45684 | D5: 10328 | E5: Dolar MEP | F5: COMPRA | G5: 81088 | H5: BONOS REP. ARG. U$SSTEP UP V.09/07/35 | I5: BONOS REP. ARG. U$S STEP UP V.09/07/35 - Dolar Cable (exterior) | J5: 2469 | K5: 66.342 | L5: 1162.22 | M5: 1637.984 | N5: 0 | O5: 0 | P5: 1637.984 | Q5: gallo-Renta Fija Dolares | R5: Dolar Cable (exterior) | S5: Origen: Gallo-Renta Fija Dolares | Fecha: 27/01/25 | Cod: 81088 | Op: COMPRA | T5: 0.66342
A6: Títulos Públicos | B6: 45706 | D6: 19864 | E6: Dolar MEP | F6: COMPRA USD | G6: 9234 | H6: BOPREAL S. 1 AVTO31/10/27 U$S CG | I6: BOPREAL S. 1 A VTO31/10/27 U$S CG - Dolar MEP (local) | J6: 40000 | K6: 96.641 | L6: 1203.16 | M6: 38656.4 | N6: 0 | O6: 0 | P6: 38656.4 | Q6: gallo-Renta Fija Dolares | R6: Dolar MEP (local) | S6: Origen: Gallo-Renta Fija Dolares | Fecha: 18/02/25 | Cod: 09234 | Op: COMPRA USD | T6: 0.96641
A7: Títulos Públicos | B7: 45713 | D7: 22758 | E7: Dolar MEP | F7: VENTA USD | G7: 9234 | H7: BOPREAL S. 1 AVTO31/10/27 U$S CG | I7: BOPREAL S. 1 A VTO31/10/27 U$S CG - Dolar MEP (local) | J7: -11513 | K7: 98.178 | L7: 1211.96 | M7: -11303.233 | N7: 0 | O7: 0 | P7: -11303.233 | Q7: gallo-Renta Fija Dolares | R7: Dolar MEP (local) | S7: Origen: Gallo-Renta Fija Dolares | Fecha: 25/02/25 | Cod: 09234 | Op: VENTA USD | T7: 0.98178
A8: Títulos Públicos | B8: 45721 | D8: 24990 | E8: Dolar MEP | F8: COMPRA USD | G8: 9234 | H8: BOPREAL S. 1 AVTO31/10/27 U$S CG | I8: BOPREAL S. 1 A VTO31/10/27 U$S CG - Dolar MEP (local) | J8: 50000 | K8: 97.243 | L8: 1235.31 | M8: 48621.5 | N8: 0 | O8: 0 | P8: 48621.5 | Q8: gallo-Renta Fija Dolares | R8: Dolar MEP (local) | S8: Origen: Gallo-Renta Fija Dolares | Fecha: 05/03/25 | Cod: 09234 | Op: COMPRA USD | T8: 0.97243
A9: Títulos Públicos | B9: 45736 | D9: 32210 | E9: Dolar MEP | F9: VENTA | G9: 9234 | H9: BOPREAL S. 1 AVTO31/10/27 U$S CG | I9: BOPREAL S. 1 A VTO31/10/27 U$S CG - Dolar MEP (local) | J9: -150000 | K9: 98.484 | L9: 1287.59 | M9: -147726 | N9: 0 | O9: 0 | P9: -147726 | Q9: gallo-Renta Fija Dolares | R9: Dolar MEP (local) | S9: Origen: Gallo-Renta Fija Dolares | Fecha: 20/03/25 | Cod: 09234 | Op: VENTA | T9: 0.98484
A10: Títulos Públicos | B10: 45748 | D10: 36434 | E10: Dolar MEP | F10: VENTA USD | G10: 9234 | H10: BOPREAL S. 1 AVTO31/10/27 U$S CG | I10: BOPREAL S. 1 A VTO31/10/27 U$S CG - Dolar MEP (local) | J10: -139860 | K10: 98.453 | L10: 1314.47 | M10: -137696.37 | N10: 0 | O10: 0 | P10: -137696.37 | Q10: gallo-Renta Fija Dolares | R10: Dolar MEP (local) | S10: Origen: Gallo-Renta Fija Dolares | Fecha: 01/04/25 | Cod: 09234 | Op: VENTA USD | T10: 0.98453
A11: Títulos Públicos | B11: 45758 | D11: 41129 | E11: Dolar MEP | F11: COMPRA USD | G11: 9234 | H11: BOPREAL S. 1 AVTO31/10/27 U$S CG | I11: BOPREAL S. 1 A VTO31/10/27 U$S CG - Dolar MEP (local) | J11: 17899 | K11: 97.243 | L11: 1333.33 | M11: 17405.525 | N11: 0 | O11: 0 | P11: 17405.525 | Q11: gallo-Renta Fija Dolares | R11: Dolar MEP (local) | S11: Origen: Gallo-Renta Fija Dolares | Fecha: 11/04/25 | Cod: 09234 | Op: COMPRA USD | T11: 0.97243
A12: Títulos Públicos | B12: 45758 | D12: 41194 | E12: Dolar MEP | F12: COMPRA USD | G12: 9234 | H12: BOPREAL S. 1 AVTO31/10/27 U$S CG | I12: BOPREAL S. 1 A VTO31/10/27 U$S CG - Dolar MEP (local) | J12: 32101 | K12: 97.242 | L12: 1333.33 | M12: 31215.654 | N12: 0 | O12: 0 | P12: 31215.654 | Q12: gallo-Renta Fija Dolares | R12: Dolar MEP (local) | S12: Origen: Gallo-Renta Fija Dolares | Fecha: 11/04/25 | Cod: 09234 | Op: COMPRA USD | T12: 0.97242
A13: Títulos Públicos | B13: 45761 | D13: 42082 | E13: Dolar MEP | F13: VENTA USD | G13: 9234 | H13: BOPREAL S. 1 AVTO31/10/27 U$S CG | I13: BOPREAL S. 1 A VTO31/10/27 U$S CG - Dolar MEP (local) | J13: -23664 | K13: 97.755 | L13: 1253.4 | M13: -23132.743 | N13: 0 | O13: 0 | P13: -23132.743 | Q13: gallo-Renta Fija Dolares | R13: Dolar MEP (local) | S13: Origen: Gallo-Renta Fija Dolares | Fecha: 14/04/25 | Cod: 09234 | Op: VENTA USD | T13: 0.97755
A14: Títulos Públicos | B14: 45768 | D14: 43617 | E14: Dolar MEP | F14: VENTA USD | G14: 9234 | H14: BOPREAL S. 1 AVTO31/10/27 U$S CG | I14: BOPREAL S. 1 A VTO31/10/27 U$S CG - Dolar MEP (local) | J14: -23296 | K14: 98.952 | L14: 1122.08 | M14: -23051.858 | N14: 0 | O14: 0 | P14: -23051.858 | Q14: gallo-Renta Fija Dolares | R14: Dolar MEP (local) | S14: Origen: Gallo-Renta Fija Dolares | Fecha: 21/04/25 | Cod: 09234 | Op: VENTA USD | T14: 0.98952
A15: Títulos Públicos | B15: 45861 | C15: 24/7/2025 | D15: 87737 | E15: Dolar ME | F15: Compra Contado | G15: 5921 | H15: BONO REP. ARGENT | I15: BONO REP. ARGENTINA USD STEP UP 2030 - Dolar MEP (local) | J15: 17044 | K15: 0.5867 | L15: 1264.65 | M15: 99.997148 | N15: 0 | O15: 0 | P15: 99.997148 | Q15: Visual | R15: Dolar MEP (local) | S15: Origen: Visual | Fecha: 23/7/2025 | Cod: 5921 | Op: Compra Contado | T15: 0.005867
A16: Títulos Públicos | B16: 45861 | C16: 24/7/2025 | D16: 87738 | E16: Dolar ME | F16: Compra Contado | G16: 81086 | H16: BONOS REP. ARG. | I16: BONOS REP. ARG. U$S STEP UP V.09/07/30 - Dolar Cable (exterior) | J16: 19884 | K16: 0.6035 | L16: 1264.65 | M16: 119.99994 | N16: 0 | O16: 0 | P16: 119.99994 | Q16: Visual | R16: Dolar Cable (exterior) | S16: Origen: Visual | Fecha: 23/7/2025 | Cod: 81086 | Op: Compra Contado | T16: 0.006035
A17: Títulos Públicos | B17: 45862 | C17: 25/7/2025 | D17: 88405 | E17: Dolar Cabl | F17: Compra Contado | G17: 81086 | H17: BONOS REP. ARG. | I17: BONOS REP. ARG. U$S STEP UP V.09/07/30 - Dolar Cable (exterior) | J17: 11477 | K17: 0.6099 | L17: 1272.91 | M17: 69.998223 | N17: 0 | O17: 0 | P17: 69.998223 | Q17: Visual | R17: Dolar Cable (exterior) | S17: Origen: Visual | Fecha: 24/7/2025 | Cod: 81086 | Op: Compra Contado | T17: 0.006099
A18: Títulos Públicos | B18: 45863 | C18: 28/7/2025 | D18: 88993 | E18: Pesos | F18: Compra Contado | G18: 9235 | H18: BOPREAL S. 1 B VT | I18: BOPREAL S. 1 B VTO31/10/27 U$S CG - Dolar MEP (local) | J18: 10519 | K18: 1277.3276 | L18: 1 | M18: 134362.09 | N18: 0 | O18: 34934.14 | P18: 169296.23 | Q18: Visual | R18: Dolar MEP (local) | S18: Origen: Visual | Fecha: 25/7/2025 | Cod: 9235 | Op: Compra Contado | T18: 12.773276
A19: Títulos Públicos | B19: 45863 | C19: 28/7/2025 | D19: 88994 | E19: Pesos | F19: Venta Contado | G19: 9247 | H19: BOPREAL S.3 VTO3 | I19: BOPREAL S.3 VTO31/05/26 U$S CG - Dolar MEP (local) | J19: -10400 | K19: 1292 | L19: 1 | M19: -134368 | N19: 0 | O19: -34935.68 | P19: -99432.32 | Q19: Visual | R19: Dolar MEP (local) | S19: Origen: Visual | Fecha: 25/7/2025 | Cod: 9247 | Op: Venta Contado | T19: 12.92
A20: Títulos Públicos | B20: 45992 | C20: 1/12/2025 | D20: 160497 | E20: Dolar ME | F20: Venta Contado | G20: 5921 | H20: BONO REP. ARGENT | I20: BONO REP. ARGENTINA USD STEP UP 2030 - Dolar MEP (local) | J20: -5544 | K20: 0.6474 | L20: 1475.23 | M20: -35.891856 | N20: 0 | O20: 8.97 | P20: -44.861856 | Q20: Visual | R20: Dolar MEP (local) | S20: Origen: Visual | Fecha: 1/12/2025 | Cod: 5921 | Op: Venta Contado | T20: 0.006474
A21: Títulos Públicos | B21: 45992 | C21: 1/12/2025 | D21: 160496 | E21: Dolar Cabl | F21: Compra Contado | G21: 5921 | H21: BONO REP. ARGENT | I21: BONO REP. ARGENTINA USD STEP UP 2030 - Dolar MEP (local) | J21: 5544 | K21: 0.6313 | L21: 1475.23 | M21: 34.999272 | N21: 0 | O21: 0 | P21: 34.999272 | Q21: Visual | R21: Dolar MEP (local) | S21: Origen: Visual | Fecha: 1/12/2025 | Cod: 5921 | Op: Compra Contado | T21: 0.006313
A22: Títulos Públicos | B22: 45992 | C22: 2/12/2025 | D22: 160848 | E22: Pesos | F22: Compra Contado | G22: 5922 | H22: BONO REP. ARGENT | I22: BONO REP. ARGENTINA USD STEP UP 2035 - Dolar MEP (local) | J22: 549 | K22: 1092.8 | L22: 1 | M22: 5999.472 | N22: 0 | O22: 1559.86 | P22: 7559.332 | Q22: Visual | R22: Dolar MEP (local) | S22: Origen: Visual | Fecha: 1/12/2025 | Cod: 5922 | Op: Compra Contado | T22: 10.928

Sheet Cauciones Tomadoras
A1: Concertación | B1: Plazo | C1: Liquidación | D1: Operación | E1: Boleto | F1: Contado | G1: Futuro | H1: Tipo de Cambio | I1: Tasa (%) | J1: Interés Bruto | K1: Interés Devengado | L1: Aranceles | M1: Derechos | N1: Costo Financiero | O1: Moneda | P1: Origen | Q1: Auditoría
A2: 45656 | B2: 3 | C2: 45659 | D2: TOM CAU TER | E2: 136345 | F2: -99974060 | G2: -1.0026987e+08 | H2: 1 | J2: -295813.66 | K2: -295813.66 | L2: -32151.54 | M2: 0 | N2: -327965.2 | O2: Pesos | P2: Gallo-Cauciones Pesos | Q2: Origen: Gallo-Cauciones Pesos
A3: 45656 | B3: 3 | C3: 45659 | D3: TOM CAU TER | E3: 136007 | F3: -199825.93 | G3: -199834.14 | H3: 1167.806 | J3: -8.21 | K3: -8.21 | L3: -19.75 | M3: 0 | N3: -27.96 | O3: Dolar MEP | P3: Gallo-Cauciones Dolares | Q3: Origen: Gallo-Cauciones Dolares
A4: 45659 | B4: 1 | C4: 45660 | D4: TOM CAU TER | E4: 421 | F4: -1.0030203e+08 | G4: -1.0039642e+08 | H4: 1 | J4: -94393.82 | K4: -94393.82 | L4: -10730.66 | M4: 0 | N4: -105124.48 | O4: Pesos | P4: Gallo-Cauciones Pesos | Q4: Origen: Gallo-Cauciones Pesos
A5: 45659 | B5: 1 | C5: 45660 | D5: TOM CAU TER | E5: 419 | F5: -199853.89 | G5: -199856.57 | H5: 1167.806 | J5: -2.68 | K5: -2.68 | L5: -6.58 | M5: 0 | N5: -9.26 | O5: Dolar MEP | P5: Gallo-Cauciones Dolares | Q5: Origen: Gallo-Cauciones Dolares
A6: 45660 | B6: 3 | C6: 45663 | D6: TOM CAU TER | E6: 1007 | F6: -1.0040715e+08 | G6: -1.0066958e+08 | H6: 1 | J6: -262434.03 | K6: -262434.03 | L6: -32279.7 | M6: 0 | N6: -294713.73 | O6: Pesos | P6: Gallo-Cauciones Pesos | Q6: Origen: Gallo-Cauciones Pesos
A7: 45660 | B7: 3 | C7: 45663 | D7: TOM CAU TER | E7: 1005 | F7: -199863.15 | G7: -199871.2 | H7: 1167.806 | J7: -8.05 | K7: -8.05 | L7: -19.75 | M7: 0 | N7: -27.8 | O7: Dolar MEP | P7: Gallo-Cauciones Dolares | Q7: Origen: Gallo-Cauciones Dolares
A8: 45663 | B8: 4 | C8: 45667 | D8: TOM CAU TER | E8: 1561 | F8: -1.0070186e+08 | G8: -1.0104364e+08 | H8: 1 | J8: -341779.37 | K8: -341779.37 | L8: -43199.48 | M8: 0 | N8: -384978.85 | O8: Pesos | P8: Gallo-Cauciones Pesos | Q8: Origen: Gallo-Cauciones Pesos
A9: 45663 | B9: 1 | C9: 45664 | D9: TOM CAU TER | E9: 1559 | F9: -199890.95 | G9: -199893.63 | H9: 1167.806 | J9: -2.68 | K9: -2.68 | L9: -6.58 | M9: 0 | N9: -9.26 | O9: Dolar MEP | P9: Gallo-Cauciones Dolares | Q9: Origen: Gallo-Cauciones Dolares
A10: 45664 | B10: 1 | C10: 45665 | D10: TOM CAU TER | E10: 2137 | F10: -199900.21 | G10: -199902.4 | H10: 1167.806 | J10: -2.19 | K10: -2.19 | L10: -6.58 | M10: 0 | N10: -8.77 | O10: Dolar MEP | P10: Gallo-Cauciones Dolares | Q10: Origen: Gallo-Cauciones Dolares
A11: 45665 | B11: 1 | C11: 45666 | D11: TOM CAU TER | E11: 2724 | F11: -199908.98 | G11: -199911.11 | H11: 1167.806 | J11: -2.13 | K11: -2.13 | L11: -6.58 | M11: 0 | N11: -8.71 | O11: Dolar MEP | P11: Gallo-Cauciones Dolares | Q11: Origen: Gallo-Cauciones Dolares
A12: 45666 | B12: 1 | C12: 45667 | D12: TOM CAU TER | E12: 3258 | F12: -199917.69 | G12: -199919.78 | H12: 1167.806 | J12: -2.09 | K12: -2.09 | L12: -6.58 | M12: 0 | N12: -8.67 | O12: Dolar MEP | P12: Gallo-Cauciones Dolares | Q12: Origen: Gallo-Cauciones Dolares
A13: 45667 | B13: 3 | C13: 45670 | D13: TOM CAU TER | E13: 3942 | F13: -1.0108684e+08 | G13: -1.0132613e+08 | H13: 1 | J13: -239285.02 | K13: -239285.02 | L13: -32490.22 | M13: 0 | N13: -271775.24 | O13: Pesos | P13: Gallo-Cauciones Pesos | Q13: Origen: Gallo-Cauciones Pesos
... A57: 45769 | B57: 1 | C57: 45770 | D57: TOM CAU TER | E57: 45476 | F57: -387.81 | G57: -387.83 | H57: 1167.806 | J57: -0.02 | K57: -0.02 | L57: 0 | M57: 0 | N57: -0.02 | O57: Dolar MEP | P57: Gallo-Cauciones Dolares | Q57: Origen: Gallo-Cauciones Dolares

Sheet Cauciones Colocadoras
A1: Concertación | B1: Plazo | C1: Liquidación | D1: Operación | E1: Boleto | F1: Contado | G1: Futuro | H1: Tipo de Cambio | I1: Tasa (%) | J1: Interés Bruto | K1: Interés Devengado | L1: Aranceles | M1: Derechos | N1: Costo Financiero | O1: Moneda | P1: Origen | Q1: Auditoría
A2: 45748 | B2: 2 | C2: 45750 | D2: COL CAU TER | E2: 37507 | F2: 132513.29 | G2: 132557.58 | H2: 1167.806 | J2: 44.29 | K2: 44.29 | L2: 1.61 | M2: 0 | N2: 42.68 | O2: Dolar MEP | P2: Gallo-Cauciones Dolares | Q2: Origen: Gallo-Cauciones Dolares
A3: 45748 | B3: 2 | C3: 45750 | D3: COL CAU TER | E3: 37508 | F3: 5183.43 | G3: 5185.16 | H3: 1167.806 | J3: 1.73 | K3: 1.73 | L3: 0.05 | M3: 0 | N3: 1.68 | O3: Dolar MEP | P3: Gallo-Cauciones Dolares | Q3: Origen: Gallo-Cauciones Dolares

Sheet Rentas y Dividendos Gallo
A1: Tipo de Instrumento | B1: Concertación | C1: Liquidación | D1: Nro. Boleto | E1: Moneda | F1: Tipo Operación | G1: Cod.Instrum | H1: Instrumento Crudo | I1: InstrumentoConMoneda | J1: Cantidad | K1: Precio | L1: Tipo Cambio | M1: Bruto | N1: Interés | O1: Gastos | P1: Costo | Q1: Neto Calculado | R1: Origen | S1: moneda emision | T1: Auditoría
A2: Títulos Públicos | B2: 45667 | D2: 2018 | E2: Dolar MEP | F2: RENTA | G2: 81086 | H2: BONOS REP. ARG. U$SSTEP UP V.09/07/30 | I2: BONOS REP. ARG. U$S STEP UP V.09/07/30 - Dolar Cable (exterior) | J2: 0 | K2: 0 | L2: 1164.01 | M2: 5.4 | N2: 0 | O2: 0.48 | P2: 0 | Q2: -5.88 | R2: Gallo-Renta Fija Dolares | S2: Dolar Cable (exterior) | T2: Origen: Gallo-Renta Fija Dolares | Operación: RENTA
A3: Títulos Públicos | B3: 45667 | D3: 2018 | E3: Dolar MEP | F3: AMORTIZACION | G3: 81086 | H3: BONOS REP. ARG. U$SSTEP UP V.09/07/30 | I3: BONOS REP. ARG. U$S STEP UP V.09/07/30 - Dolar Cable (exterior) | J3: 120 | K3: 1 | L3: 1164.01 | M3: 120 | N3: 0 | O3: 0 | P3: 0.4902 | Q3: -0.4902 | R3: Gallo-Renta Fija Dolares | S3: Dolar Cable (exterior) | T3: Origen: Gallo-Renta Fija Dolares | Operación: AMORTIZACION
A4: Títulos Públicos | B4: 45667 | D4: 1881 | E4: Dolar MEP | F4: RENTA | G4: 81088 | H4: BONOS REP. ARG. U$SSTEP UP V.09/07/35 | I4: BONOS REP. ARG. U$S STEP UP V.09/07/35 - Dolar Cable (exterior) | J4: 0 | K4: 0 | L4: 1164.01 | M4: 3.76 | N4: 0 | O4: 35.4 | P4: 0 | Q4: -39.16 | R4: Gallo-Renta Fija Dolares | S4: Dolar Cable (exterior) | T4: Origen: Gallo-Renta Fija Dolares | Operación: RENTA
A5: Obligaciones Negociables | B5: 45680 | D5: 2595 | E5: Dolar MEP | F5: RENTA | G5: 83849 | H5: TELECOM ARGENT 144A9.5% VTO. 18/07/31 | I5: TELECOM ARGENT 144A 9.5% VTO. 18/07/31 - Dolar Cable (exterior) | J5: 0 | K5: 0 | L5: 1167.35 | M5: 0.4 | N5: 0 | O5: 3.87 | P5: 0 | Q5: -4.27 | R5: Gallo-Renta Fija Dolares | S5: Dolar Cable (exterior) | T5: Origen: Gallo-Renta Fija Dolares | Operación: RENTA
A6: Títulos Públicos | B6: 45684 | D6: 2656 | E6: Dolar MEP | F6: RENTA | G6: 32804 | H6: TD PUB. PCIA. CORDOBAV.27/10/26 | I6: TD PUB.PCIA. CORDOBA 1 V.27/10/26 USD CG - Dolar MEP (local) | J6: 0 | K6: 0 | L6: 1162.22 | M6: 40.07 | N6: 0 | O6: 0.66 | P6: 0 | Q6: -40.73 | R6: Gallo-Renta Fija Dolares | S6: Dolar MEP (local) | T6: Origen: Gallo-Renta Fija Dolares | Operación: RENTA
A7: Títulos Públicos | B7: 45684 | D7: 2656 | E7: Dolar MEP | F7: AMORTIZACION | G7: 32804 | H7: TD PUB. PCIA. CORDOBAV.27/10/26 | I7: TD PUB.PCIA. CORDOBA 1 V.27/10/26 USD CG - Dolar MEP (local) | J7: 281.25 | K7: 1 | L7: 1162.22 | M7: 281.25 | N7: 0 | O7: 0 | P7: 59.0619 | Q7: -59.0619 | R7: Gallo-Renta Fija Dolares | S7: Dolar MEP (local) | T7: Origen: Gallo-Renta Fija Dolares | Operación: AMORTIZACION
A8: Títulos Públicos | B8: 45716 | D8: 3654 | E8: Dolar MEP | F8: RENTA | G8: 9247 | H8: BOPREAL S.3 VTO31/05/26U$S CG | I8: BOPREAL S.3 VTO31/05/26 U$S CG - Dolar MEP (local) | J8: 0 | K8: 0 | L8: 1228.48 | M8: 76.26 | N8: 0 | O8: 0.83 | P8: 0 | Q8: -77.09 | R8: Gallo-Renta Fija Dolares | S8: Dolar MEP (local) | T8: Origen: Gallo-Renta Fija Dolares | Operación: RENTA
A9: Obligaciones Negociables | B9: 45722 | D9: 3852 | E9: Pesos | F9: AMORTIZACION | G9: 81993 | H9: ON GENNEIA SA REGS8,75% V.02/09/2027 | I9: ON GENNEIA SA REGS 8,75% V.02/ - Dolar Cable (exterior) | J9: 1500 | K9: 1 | L9: 1 | M9: 1500 | N9: 0 | O9: 0 | P9: 10145.715 | Q9: -10145.715 | R9: Gallo-Renta Fija Pesos | S9: Dolar Cable (exterior) | T9: Origen: Gallo-Renta Fija Pesos | Operación: AMORTIZACION
A10: Obligaciones Negociables | B10: 45722 | D10: 3943 | E10: Pesos | F10: RENTA | G10: 81993 | H10: ON GENNEIA SA REGS8,75% V.02/09/2027 | I10: ON GENNEIA SA REGS 8,75% V.02/ - Dolar Cable (exterior) | J10: 0 | K10: 0 | L10: 1 | M10: 393.75 | N10: 0 | O10: 0 | P10: 0 | Q10: -393.75 | R10: Gallo-Renta Fija Pesos | S10: Dolar Cable (exterior) | T10: Origen: Gallo-Renta Fija Pesos | Operación: RENTA
A11: Obligaciones Negociables | B11: 45730 | D11: 4250 | E11: Dolar MEP | F11: RENTA | G11: 83928 | H11: YPF SOCIEDAD ON 8.75%VTO. 11/09/31 | I11: YPF SOCIEDAD ON 8.75% VTO. 11/09/31 - Dolar Cable (exterior) | J11: 0 | K11: 0 | L11: 1237.78 | M11: 0.43 | N11: 0 | O11: 4.3 | P11: 0 | Q11: -4.73 | R11: Gallo-Renta Fija Dolares | S11: Dolar Cable (exterior) | T11: Origen: Gallo-Renta Fija Dolares | Operación: RENTA
A12: Títulos Públicos | B12: 45775 | D12: 5771 | E12: Dolar MEP | F12: RENTA | G12: 32804 | H12: TD PUB. PCIA. CORDOBAV.27/10/26 | I12: TD PUB.PCIA. CORDOBA 1 V.27/10/26 USD CG - Dolar MEP (local) | J12: 0 | K12: 0 | L12: 1176.55 | M12: 35.06 | N12: 0 | O12: 0.67 | P12: 0 | Q12: -35.73 | R12: Gallo-Renta Fija Dolares | S12: Dolar MEP (local) | T12: Origen: Gallo-Renta Fija Dolares | Operación: RENTA
A13: Títulos Públicos | B13: 45775 | D13: 5771 | E13: Dolar MEP | F13: AMORTIZACION | G13: 32804 | H13: TD PUB. PCIA. CORDOBAV.27/10/26 | I13: TD PUB.PCIA. CORDOBA 1 V.27/10/26 USD CG - Dolar MEP (local) | J13: 281.25 | K13: 1 | L13: 1176.55 | M13: 281.25 | N13: 0 | O13: 0 | P13: 59.0619 | Q13: -59.0619 | R13: Gallo-Renta Fija Dolares | S13: Dolar MEP (local) | T13: Origen: Gallo-Renta Fija Dolares | Operación: AMORTIZACION
A14: Cedears | B14: 45806 | D14: 7174 | E14: Pesos | F14: DIVIDENDO | G14: 8524 | H14: CEDEAR TENARIS S.A.(ADS) | I14: CEDEAR TENARIS S.A. (ADS) - Pesos | J14: 0 | K14: 0 | L14: 1 | M14: 86.21 | N14: 0 | O14: 0 | P14: 0 | Q14: -86.21 | R14: Gallo-Tit.Privados Exentos | S14: Pesos | T14: Origen: Gallo-Tit.Privados Exentos | Operación: DIVIDENDO
A15: Títulos Públicos | B15: 45810 | C15: 2/6/2025 | D15: 205 | E15: Dolar MEP | F15: RENTA | G15: 9247 | H15: BOPREAL S.3 VTO31/05/26 U$S CG | I15: BOPREAL S.3 VTO31/05/26 U$S CG - Dolar MEP (local) | J15: 0 | K15: 1 | L15: 1183.78 | M15: 77.53 | N15: 0 | O15: 0.47 | P15: 0 | Q15: -78 | R15: Visual-Rentas Dividendos USD | S15: Dolar MEP (local) | T15: Origen: Visual-Rentas Dividendos USD | Cat: Rentas | Op: Renta
A16: Acciones | B16: 45819 | C16: 11/6/2025 | D16: 2623 | E16: Pesos | F16: DIVIDENDO EN EFECTIVO | G16: 617 | H16: TRANSPORTADORA DE GAS DEL SUR ORDS. B 1 V | I16: TRANSPORTADORA DE GAS DEL SUR ORDS. B 1 V - Pesos | J16: 0 | K16: 1 | L16: 1 | M16: 653425.95 | N16: 0 | O16: 2679.07 | P16: 0 | Q16: -656105.02 | R16: Visual-Rentas Dividendos ARS | S16: Pesos | T16: Origen: Visual-Rentas Dividendos ARS | Cat: Dividendos | Op: Dividendo en efectivo
A17: Obligaciones Negociables | B17: 45819 | C17: 11/6/2025 | D17: 2701 | E17: Dolar Cable | F17: RENTA | G17: 82445 | H17: ON PAMPA ENERGIA SA REGS 9.5% | I17: ON PAMPA ENERGIA SA REGS 9.5% - Dolar Cable (exterior) | J17: 0 | K17: 1 | L17: 1186.93 | M17: 126.53 | N17: 0 | O17: 0.77 | P17: 0 | Q17: -127.3 | R17: Visual-Rentas Dividendos USD | S17: Dolar Cable (exterior) | T17: Origen: Visual-Rentas Dividendos USD | Cat: Rentas | Op: Renta
A18: Títulos Públicos | B18: 45848 | C18: 10/7/2025 | D18: 10080 | E18: Dolar MEP | F18: AMORTIZACIÓN | G18: 5927 | H18: BONO REP ARGENTINA USD 1% 2029 | I18: BONO REP ARGENTINA USD 1% 2029 - Dolar MEP (local) | J18: 467.1 | K18: 1 | L18: 1267.87 | M18: 0 | N18: 0 | O18: 0 | P18: 0 | Q18: 467.1 | R18: Visual-Rentas Dividendos USD | S18: Dolar MEP (local) | T18: Origen: Visual-Rentas Dividendos USD | Cat: Rentas | Op: Amortización
A19: Títulos Públicos | B19: 45848 | C19: 10/7/2025 | D19: 10219 | E19: Dolar MEP | F19: RENTA | G19: 5927 | H19: BONO REP ARGENTINA USD 1% 2029 | I19: BONO REP ARGENTINA USD 1% 2029 - Dolar MEP (local) | J19: 0 | K19: 1 | L19: 1267.87 | M19: 20.95 | N19: 0 | O19: 0.06 | P19: 0 | Q19: -21.01 | R19: Visual-Rentas Dividendos USD | S19: Dolar MEP (local) | T19: Origen: Visual-Rentas Dividendos USD | Cat: Rentas | Op: Renta
A20: Títulos Públicos | B20: 45848 | C20: 10/7/2025 | D20: 10668 | E20: Dolar MEP | F20: AMORTIZACIÓN | G20: 5921 | H20: BONO REP. ARGENTINA USD STEP UP 2030 | I20: BONO REP. ARGENTINA USD STEP UP 2030 - Dolar MEP (local) | J20: 2509.84 | K20: 1 | L20: 1267.87 | M20: 0 | N20: 0 | O20: 0 | P20: 0 | Q20: 2509.84 | R20: Visual-Rentas Dividendos USD | S20: Dolar MEP (local) | T20: Origen: Visual-Rentas Dividendos USD | Cat: Rentas | Op: Amortización
A21: Títulos Públicos | B21: 45848 | C21: 10/7/2025 | D21: 10443 | E21: Dolar MEP | F21: RENTA | G21: 5921 | H21: BONO REP. ARGENTINA USD STEP UP 2030 | I21: BONO REP. ARGENTINA USD STEP UP 2030 - Dolar MEP (local) | J21: 0 | K21: 1 | L21: 1267.87 | M21: 103.22 | N21: 0 | O21: 0.31 | P21: 0 | Q21: -103.53 | R21: Visual-Rentas Dividendos USD | S21: Dolar MEP (local) | T21: Origen: Visual-Rentas Dividendos USD | Cat: Rentas | Op: Renta
A22: Títulos Públicos | B22: 45848 | C22: 10/7/2025 | D22: 11314 | E22: Dolar MEP | F22: RENTA | G22: 5922 | H22: BONO REP. ARGENTINA USD STEP UP 2035 | I22: BONO REP. ARGENTINA USD STEP UP 2035 - Dolar MEP (local) | J22: 0 | K22: 1 | L22: 1267.87 | M22: 645.12 | N22: 0 | O22: 1.94 | P22: 0 | Q22: -647.06 | R22: Visual-Rentas Dividendos USD | S22: Dolar MEP (local) | T22: Origen: Visual-Rentas Dividendos USD | Cat: Rentas | Op: Renta
A23: Títulos Públicos | B23: 45848 | C23: 10/7/2025 | D23: 12454 | E23: Dolar Cable | F23: AMORTIZACIÓN | G23: 81086 | H23: BONOS REP. ARG. U$S STEP UP V.09/07/30 | I23: BONOS REP. ARG. U$S STEP UP V.09/07/30 - Dolar Cable (exterior) | J23: 120 | K23: 1 | L23: 1267.87 | M23: 0 | N23: 0 | O23: 0 | P23: 0 | Q23: 120 | R23: Visual-Rentas Dividendos USD | S23: Dolar Cable (exterior) | T23: Origen: Visual-Rentas Dividendos USD | Cat: Rentas | Op: Amortización
A24: Títulos Públicos | B24: 45848 | C24: 10/7/2025 | D24: 12183 | E24: Dolar Cable | F24: RENTA | G24: 81086 | H24: BONOS REP. ARG. U$S STEP UP V.09/07/30 | I24: BONOS REP. ARG. U$S STEP UP V.09/07/30 - Dolar Cable (exterior) | J24: 0 | K24: 1 | L24: 1267.87 | M24: 4.94 | N24: 0 | O24: 0.01 | P24: 0 | Q24: -4.95 | R24: Visual-Rentas Dividendos USD | S24: Dolar Cable (exterior) | T24: Origen: Visual-Rentas Dividendos USD | Cat: Rentas | Op: Renta
A25: Títulos Públicos | B25: 45848 | C25: 10/7/2025 | D25: 12105 | E25: Dolar Cable | F25: RENTA | G25: 81088 | H25: BONOS REP. ARG. U$S STEP UP V.09/07/35 | I25: BONOS REP. ARG. U$S STEP UP V.09/07/35 - Dolar Cable (exterior) | J25: 0 | K25: 1 | L25: 1267.87 | M25: 4393.66 | N25: 0 | O25: 13.26 | P25: 0 | Q25: -4406.92 | R25: Visual-Rentas Dividendos USD | S25: Dolar Cable (exterior) | T25: Origen: Visual-Rentas Dividendos USD | Cat: Rentas | Op: Renta
A26: Obligaciones Negociables | B26: 45863 | C26: 25/7/2025 | D26: 17382 | E26: Dolar Cable | F26: RENTA | G26: 83849 | H26: TELECOM ARGENT 144A 9.5% VTO. 18/07/31 | I26: TELECOM ARGENT 144A 9.5% VTO. 18/07/31 - Dolar Cable (exterior) | J26: 0 | K26: 1 | L26: 1285.98 | M26: 472.13 | N26: 0 | O26: 2.87 | P26: 0 | Q26: -475 | R26: Visual-Rentas Dividendos USD | S26: Dolar Cable (exterior) | T26: Origen: Visual-Rentas Dividendos USD | Cat: Rentas | Op: Renta
... A37: Cedears | B37: 45996 | C37: 5/12/2025 | D37: 58476 | E37: Pesos | F37: DIVIDENDO EN EFECTIVO | G37: 8524 | H37: CEDEAR TENARIS S.A. (ADS) | I37: CEDEAR TENARIS S.A. (ADS) - Pesos | J37: 0 | K37: 1 | L37: 1 | M37: 63609.57 | N37: 0 | O37: 388.51 | P37: 0 | Q37: -63998.08 | R37: Visual-Rentas Dividendos ARS | S37: Pesos | T37: Origen: Visual-Rentas Dividendos ARS | Cat: Dividendos | Op: Dividendo en efectivo

Sheet Resultado Ventas ARS
A1: Origen | B1: Tipo de Instrumento | C1: Instrumento | D1: Cod.Instrum | E1: Concertación | F1: Liquidación | G1: Moneda | H1: Tipo Operación | I1: Cantidad | J1: Precio | K1: Bruto | L1: Interés | M1: Tipo de Cambio | N1: Gastos | O1: IVA | P1: Resultado | Q1: Cantidad Stock Inicial | R1: Precio Stock Inicial | S1: Costo por venta(gallo) | T1: Neto Calculado(visual) | U1: Resultado Calculado(final) | V1: Cantidad de Stock Final | W1: Precio Stock Final | X1: Explicación Q | Y1: Explicación R-U | Z1: chequeado | AA1: Precio Nominal
A2: gallo-Renta Fija Pesos | B2: Títulos Públicos | C2: BONO TESORO NACI CAP V.13/02/26 $ CG - Pesos | D2: 9314 | E2: 45681 | G2: Pesos | H2: VENTA | I2: -95498084 | J2: 109.3 | K2: -1.0437941e+08 | L2: 0 | M2: 1 | N2: 0 | O2: 0 | Q2: 95498084 | R2: 1.04661 | S2: -99949250 | T2: -1.0437941e+08 | U2: 4430156.1 | V2: 0 | W2: 0 | X2: BUSCARV(D2→Posicion Inicial Gallo col V=Precio Nominal, fallback PrecioTenenciasIniciales/PreciosInicialesEspecies) | Y2: R=Precio stock previo | S=-95498084*R2=-95498084*[stock price] | T=K2+L2=-10437940581.199999+0 | U=|T2|-|S2| | Z2: Origen: gallo-Renta Fija Pesos | Cod: 9314 | AA2: 1.093

Sheet Resultado Ventas USD
A1: Origen | B1: Tipo de Instrumento | C1: Instrumento | D1: Cod.Instrum | E1: Concertación | F1: Liquidación | G1: Moneda | H1: Tipo Operación | I1: Cantidad | J1: Precio | K1: Precio Standarizado | L1: Precio Standarizado en USD | M1: Bruto en USD | N1: Interés | O1: Tipo de Cambio | P1: Valor USD Dia | Q1: Gastos | R1: IVA | S1: Resultado | T1: Cantidad Stock Inicial | U1: Precio Stock USD | V1: Costo por venta(gallo) | W1: Neto Calculado(visual) | X1: Resultado Calculado(final) | Y1: Cantidad de Stock Final | Z1: Precio Stock Final | AA1: Explicación T-Z | AB1: Auditoría | AC1: Precio Nominal
A2: gallo-Renta Fija Dolares | B2: Títulos Públicos | C2: BONO REP. ARGENTINA USD STEP UP 2030 - Dolar MEP (local) | D2: 5921 | E2: 45681 | G2: Dolar MEP | H2: CPRA CABLE | I2: 7631 | J2: 65.684 | K2: 65.684 | L2: 65.684 | M2: 5012.346 | N2: 0 | O2: 1 | P2: 1155.75 | Q2: 0 | R2: 0 | T2: 0 | U2: 0.76005775 | V2: 0 | W2: 5012.346 | X2: 0 | Y2: 7631 | Z2: 0.65684 | AA2: T=BUSCARV(D2→Posicion Inicial Gallo col V=Precio Nominal, fallback PrecioTenenciasIniciales/PreciosInicialesEspecies) | U=PrecioPos/P2 | V=7631*U si venta | W=M-Q | X=|W|-|V| | Y=I+T | Z=Promedio | AB2: Origen: gallo-Renta Fija Dolares | Cod: 5921 | K(PrecioStd)=raw | L=K*O | AC2: 0.65684
A3: gallo-Renta Fija Dolares | B3: Títulos Públicos | C3: BONO REP. ARGENTINA USD STEP UP 2030 - Dolar MEP (local) | D3: 5921 | E3: 45681 | G3: Dolar MEP | H3: VENTA USD | I3: -7631 | J3: 60.935 | K3: 60.935 | L3: 60.935 | M3: -4649.9499 | N3: 0 | O3: 1 | P3: 1155.75 | Q3: 0 | R3: 0 | T3: 7631 | U3: 0.65684 | V3: -5012.346 | W3: -4649.9499 | X3: -362.39619 | Y3: 0 | Z3: 0 | AA3: SI D3=D2: Z2, SINO: BUSCARV(col V=Precio Nominal (Posicion Inicial Gallo), fallback PrecioTenenciasIniciales/PreciosInicialesEspecies) | U=PrecioPos/P3 | V=-7631*U si venta | W=M-Q | X=|W|-|V| | Y=I+T | Z=Promedio | AB3: Origen: gallo-Renta Fija Dolares | Cod: 5921 | K(PrecioStd)=raw | L=K*O | AC3: 0.60935
A4: Visual | B4: Títulos Públicos | C4: BONO REP. ARGENTINA USD STEP UP 2030 - Dolar MEP (local) | D4: 5921 | E4: 45861 | F4: 24/7/2025 | G4: Dolar ME | H4: Compra Contado | I4: 17044 | J4: 0.5867 | K4: 58.67 | L4: 58.67 | M4: 9999.7148 | N4: 0 | O4: 1 | P4: 1264.65 | Q4: 0 | R4: 0 | T4: 0 | U4: 0.65684 | V4: 0 | W4: 9999.7148 | X4: 0 | Y4: 17044 | Z4: 0.5867 | AA4: SI D4=D3: Z3, SINO: BUSCARV(col V=Precio Nominal (Posicion Inicial Gallo), fallback PrecioTenenciasIniciales/PreciosInicialesEspecies) | U=PrecioPos/P4 | V=17044*U si venta | W=M-Q | X=|W|-|V| | Y=I+T | Z=Promedio | AB4: Origen: Visual | Cod: 5921 | K(PrecioStd)=x100 | L=K*O | AC4: 0.5867
A5: Visual | B5: Títulos Públicos | C5: BONO REP. ARGENTINA USD STEP UP 2030 - Dolar MEP (local) | D5: 5921 | E5: 45992 | F5: 1/12/2025 | G5: Dolar Cabl | H5: Compra Contado | I5: 5544 | J5: 0.6313 | K5: 63.13 | L5: 63.13 | M5: 3499.9272 | N5: 0 | O5: 1 | P5: 1475.23 | Q5: 0 | R5: 0 | T5: 17044 | U5: 0.5867 | V5: 0 | W5: 3499.9272 | X5: 0 | Y5: 22588 | Z5: 0.59764663 | AA5: SI D5=D4: Z4, SINO: BUSCARV(col V=Precio Nominal (Posicion Inicial Gallo), fallback PrecioTenenciasIniciales/PreciosInicialesEspecies) | U=PrecioPos/P5 | V=5544*U si venta | W=M-Q | X=|W|-|V| | Y=I+T | Z=Promedio | AB5: Origen: Visual | Cod: 5921 | K(PrecioStd)=x100 | L=K*O | AC5: 0.6313
A6: Visual | B6: Títulos Públicos | C6: BONO REP. ARGENTINA USD STEP UP 2030 - Dolar MEP (local) | D6: 5921 | E6: 45992 | F6: 1/12/2025 | G6: Dolar ME | H6: Venta Contado | I6: -5544 | J6: 0.6474 | K6: 64.74 | L6: 64.74 | M6: -3589.1856 | N6: 0 | O6: 1 | P6: 1475.23 | Q6: 0.0897 | R6: 0.01557192 | T6: 22588 | U6: 0.59764663 | V6: -3313.3529 | W6: -3589.2753 | X6: 275.9224 | Y6: 17044 | Z6: 0.59764663 | AA6: SI D6=D5: Z5, SINO: BUSCARV(col V=Precio Nominal (Posicion Inicial Gallo), fallback PrecioTenenciasIniciales/PreciosInicialesEspecies) | U=PrecioPos/P6 | V=-5544*U si venta | W=M-Q | X=|W|-|V| | Y=I+T | Z=Promedio | AB6: Origen: Visual | Cod: 5921 | K(PrecioStd)=x100 | L=K*O | AC6: 0.6474
A7: Visual | B7: Títulos Públicos | C7: BONO REP. ARGENTINA USD STEP UP 2035 - Dolar MEP (local) | D7: 5922 | E7: 45992 | F7: 2/12/2025 | G7: Pesos | H7: Compra Contado | I7: 549 | J7: 1092.8 | K7: 109280 | L7: 74.076585 | M7: 406.68045 | N7: 0 | O7: 0.0006778604 | P7: 1475.23 | Q7: 15.5986 | R7: 2.707917 | T7: 0 | U7: 0.69900309 | V7: 0 | W7: 406.68045 | X7: 0 | Y7: 549 | Z7: 0.74076585 | AA7: SI D7=D6: Z6, SINO: BUSCARV(col V=Precio Nominal (Posicion Inicial Gallo), fallback PrecioTenenciasIniciales/PreciosInicialesEspecies) | U=PrecioPos/P7 | V=549*U si venta | W=M-Q | X=|W|-|V| | Y=I+T | Z=Promedio | AB7: Origen: Visual | Cod: 5922 | K(PrecioStd)=x100 | L=K*O | AC7: 0.74076585
A8: Visual | B8: Títulos Públicos | C8: BONOS REP. ARG. U$S STEP UP V.09/07/30 - Dolar Cable (exterior) | D8: 81086 | E8: 45861 | F8: 24/7/2025 | G8: Dolar ME | H8: Compra Contado | I8: 19884 | J8: 0.6035 | K8: 60.35 | L8: 60.35 | M8: 11999.994 | N8: 0 | O8: 1 | P8: 1264.65 | Q8: 0 | R8: 0 | T8: 1500 | U8: 0.30571048 | V8: 0 | W8: 11999.994 | X8: 0 | Y8: 21384 | Z8: 0.58261129 | AA8: SI D8=D7: Z7, SINO: BUSCARV(col V=Precio Nominal (Posicion Inicial Gallo), fallback PrecioTenenciasIniciales/PreciosInicialesEspecies) | U=PrecioPos/P8 | V=19884*U si venta | W=M-Q | X=|W|-|V| | Y=I+T | Z=Promedio | AB8: Origen: Visual | Cod: 81086 | K(PrecioStd)=x100 | L=K*O | AC8: 0.6035
A9: Visual | B9: Títulos Públicos | C9: BONOS REP. ARG. U$S STEP UP V.09/07/30 - Dolar Cable (exterior) | D9: 81086 | E9: 45862 | F9: 25/7/2025 | G9: Dolar Cabl | H9: Compra Contado | I9: 11477 | J9: 0.6099 | K9: 60.99 | L9: 60.99 | M9: 6999.8223 | N9: 0 | O9: 1 | P9: 1272.91 | Q9: 0 | R9: 0 | T9: 21384 | U9: 0.58261129 | V9: 0 | W9: 6999.8223 | X9: 0 | Y9: 32861 | Z9: 0.59214211 | AA9: SI D9=D8: Z8, SINO: BUSCARV(col V=Precio Nominal (Posicion Inicial Gallo), fallback PrecioTenenciasIniciales/PreciosInicialesEspecies) | U=PrecioPos/P9 | V=11477*U si venta | W=M-Q | X=|W|-|V| | Y=I+T | Z=Promedio | AB9: Origen: Visual | Cod: 81086 | K(PrecioStd)=x100 | L=K*O | AC9: 0.6099
A10: gallo-Renta Fija Dolares | B10: Títulos Públicos | C10: BONOS REP. ARG. U$S STEP UP V.09/07/35 - Dolar Cable (exterior) | D10: 81088 | E10: 45684 | G10: Dolar MEP | H10: COMPRA | I10: 2469 | J10: 66.342 | K10: 66.342 | L10: 66.342 | M10: 1637.984 | N10: 0 | O10: 1 | P10: 1162.22 | Q10: 0 | R10: 0 | T10: 211200 | U10: 0.48763274 | V10: 0 | W10: 1637.984 | X10: 0 | Y10: 213669 | Z10: 0.489664 | AA10: SI D10=D9: Z9, SINO: BUSCARV(col V=Precio Nominal (Posicion Inicial Gallo), fallback PrecioTenenciasIniciales/PreciosInicialesEspecies) | U=PrecioPos/P10 | V=2469*U si venta | W=M-Q | X=|W|-|V| | Y=I+T | Z=Promedio | AB10: Origen: gallo-Renta Fija Dolares | Cod: 81088 | K(PrecioStd)=raw | L=K*O | AC10: 0.66342
A11: gallo-Renta Fija Dolares | B11: Títulos Públicos | C11: BOPREAL S. 1 A VTO31/10/27 U$S CG - Dolar MEP (local) | D11: 9234 | E11: 45706 | G11: Dolar MEP | H11: COMPRA USD | I11: 40000 | J11: 96.641 | K11: 96.641 | L11: 96.641 | M11: 38656.4 | N11: 0 | O11: 1 | P11: 1203.16 | Q11: 0 | R11: 0 | T11: 208333 | U11: 0.80547891 | V11: 0 | W11: 38656.4 | X11: 0 | Y11: 248333 | Z11: 0.83140073 | AA11: SI D11=D10: Z10, SINO: BUSCARV(col V=Precio Nominal (Posicion Inicial Gallo), fallback PrecioTenenciasIniciales/PreciosInicialesEspecies) | U=PrecioPos/P11 | V=40000*U si venta | W=M-Q | X=|W|-|V| | Y=I+T | Z=Promedio | AB11: Origen: gallo-Renta Fija Dolares | Cod: 9234 | K(PrecioStd)=raw | L=K*O | AC11: 0.96641
A12: gallo-Renta Fija Dolares | B12: Títulos Públicos | C12: BOPREAL S. 1 A VTO31/10/27 U$S CG - Dolar MEP (local) | D12: 9234 | E12: 45713 | G12: Dolar MEP | H12: VENTA USD | I12: -11513 | J12: 98.178 | K12: 98.178 | L12: 98.178 | M12: -11303.233 | N12: 0 | O12: 1 | P12: 1211.96 | Q12: 0 | R12: 0 | T12: 248333 | U12: 0.83140073 | V12: -9571.9166 | W12: -11303.233 | X12: 1731.3166 | Y12: 236820 | Z12: 0.83140073 | AA12: SI D12=D11: Z11, SINO: BUSCARV(col V=Precio Nominal (Posicion Inicial Gallo), fallback PrecioTenenciasIniciales/PreciosInicialesEspecies) | U=PrecioPos/P12 | V=-11513*U si venta | W=M-Q | X=|W|-|V| | Y=I+T | Z=Promedio | AB12: Origen: gallo-Renta Fija Dolares | Cod: 9234 | K(PrecioStd)=raw | L=K*O | AC12: 0.98178
A13: gallo-Renta Fija Dolares | B13: Títulos Públicos | C13: BOPREAL S. 1 A VTO31/10/27 U$S CG - Dolar MEP (local) | D13: 9234 | E13: 45721 | G13: Dolar MEP | H13: COMPRA USD | I13: 50000 | J13: 97.243 | K13: 97.243 | L13: 97.243 | M13: 48621.5 | N13: 0 | O13: 1 | P13: 1235.31 | Q13: 0 | R13: 0 | T13: 236820 | U13: 0.83140073 | V13: 0 | W13: 48621.5 | X13: 0 | Y13: 286820 | Z13: 0.85598571 | AA13: SI D13=D12: Z12, SINO: BUSCARV(col V=Precio Nominal (Posicion Inicial Gallo), fallback PrecioTenenciasIniciales/PreciosInicialesEspecies) | U=PrecioPos/P13 | V=50000*U si venta | W=M-Q | X=|W|-|V| | Y=I+T | Z=Promedio | AB13: Origen: gallo-Renta Fija Dolares | Cod: 9234 | K(PrecioStd)=raw | L=K*O | AC13: 0.97243
A14: gallo-Renta Fija Dolares | B14: Títulos Públicos | C14: BOPREAL S. 1 A VTO31/10/27 U$S CG - Dolar MEP (local) | D14: 9234 | E14: 45736 | G14: Dolar MEP | H14: VENTA | I14: -150000 | J14: 98.484 | K14: 98.484 | L14: 98.484 | M14: -147726 | N14: 0 | O14: 1 | P14: 1287.59 | Q14: 0 | R14: 0 | T14: 286820 | U14: 0.85598571 | V14: -128397.86 | W14: -147726 | X14: 19328.144 | Y14: 136820 | Z14: 0.85598571 | AA14: SI D14=D13: Z13, SINO: BUSCARV(col V=Precio Nominal (Posicion Inicial Gallo), fallback PrecioTenenciasIniciales/PreciosInicialesEspecies) | U=PrecioPos/P14 | V=-150000*U si venta | W=M-Q | X=|W|-|V| | Y=I+T | Z=Promedio | AB14: Origen: gallo-Renta Fija Dolares | Cod: 9234 | K(PrecioStd)=raw | L=K*O | AC14: 0.98484
A15: gallo-Renta Fija Dolares | B15: Títulos Públicos | C15: BOPREAL S. 1 A VTO31/10/27 U$S CG - Dolar MEP (local) | D15: 9234 | E15: 45748 | G15: Dolar MEP | H15: VENTA USD | I15: -139860 | J15: 98.453 | K15: 98.453 | L15: 98.453 | M15: -137696.37 | N15: 0 | O15: 1 | P15: 1314.47 | Q15: 0 | R15: 0 | T15: 136820 | U15: 0.85598571 | V15: -119718.16 | W15: -137696.37 | X15: 17978.205 | Y15: -3040 | Z15: 0.85598571 | AA15: SI D15=D14: Z14, SINO: BUSCARV(col V=Precio Nominal (Posicion Inicial Gallo), fallback PrecioTenenciasIniciales/PreciosInicialesEspecies) | U=PrecioPos/P15 | V=-139860*U si venta | W=M-Q | X=|W|-|V| | Y=I+T | Z=Promedio | AB15: Origen: gallo-Renta Fija Dolares | Cod: 9234 | K(PrecioStd)=raw | L=K*O | AC15: 0.98453
A16: gallo-Renta Fija Dolares | B16: Títulos Públicos | C16: BOPREAL S. 1 A VTO31/10/27 U$S CG - Dolar MEP (local) | D16: 9234 | E16: 45758 | G16: Dolar MEP | H16: COMPRA USD | I16: 17899 | J16: 97.243 | K16: 97.243 | L16: 97.243 | M16: 17405.525 | N16: 0 | O16: 1 | P16: 1333.33 | Q16: 0 | R16: 0 | T16: -3040 | U16: 0.85598571 | V16: 0 | W16: 17405.525 | X16: 0 | Y16: 14859 | Z16: 0.99625332 | AA16: SI D16=D15: Z15, SINO: BUSCARV(col V=Precio Nominal (Posicion Inicial Gallo), fallback PrecioTenenciasIniciales/PreciosInicialesEspecies) | U=PrecioPos/P16 | V=17899*U si venta | W=M-Q | X=|W|-|V| | Y=I+T | Z=Promedio | AB16: Origen: gallo-Renta Fija Dolares | Cod: 9234 | K(PrecioStd)=raw | L=K*O | AC16: 0.97243
A17: gallo-Renta Fija Dolares | B17: Títulos Públicos | C17: BOPREAL S. 1 A VTO31/10/27 U$S CG - Dolar MEP (local) | D17: 9234 | E17: 45758 | G17: Dolar MEP | H17: COMPRA USD | I17: 32101 | J17: 97.242 | K17: 97.242 | L17: 97.242 | M17: 31215.654 | N17: 0 | O17: 1 | P17: 1333.33 | Q17: 0 | R17: 0 | T17: 14859 | U17: 0.99625332 | V17: 0 | W17: 31215.654 | X17: 0 | Y17: 46960 | Z17: 0.9799613 | AA17: SI D17=D16: Z16, SINO: BUSCARV(col V=Precio Nominal (Posicion Inicial Gallo), fallback PrecioTenenciasIniciales/PreciosInicialesEspecies) | U=PrecioPos/P17 | V=32101*U si venta | W=M-Q | X=|W|-|V| | Y=I+T | Z=Promedio | AB17: Origen: gallo-Renta Fija Dolares | Cod: 9234 | K(PrecioStd)=raw | L=K*O | AC17: 0.97242
A18: gallo-Renta Fija Dolares | B18: Títulos Públicos | C18: BOPREAL S. 1 A VTO31/10/27 U$S CG - Dolar MEP (local) | D18: 9234 | E18: 45761 | G18: Dolar MEP | H18: VENTA USD | I18: -23664 | J18: 97.755 | K18: 97.755 | L18: 97.755 | M18: -23132.743 | N18: 0 | O18: 1 | P18: 1253.4 | Q18: 0 | R18: 0 | T18: 46960 | U18: 0.9799613 | V18: -23189.804 | W18: -23132.743 | X18: -57.0609 | Y18: 23296 | Z18: 0.9799613 | AA18: SI D18=D17: Z17, SINO: BUSCARV(col V=Precio Nominal (Posicion Inicial Gallo), fallback PrecioTenenciasIniciales/PreciosInicialesEspecies) | U=PrecioPos/P18 | V=-23664*U si venta | W=M-Q | X=|W|-|V| | Y=I+T | Z=Promedio | AB18: Origen: gallo-Renta Fija Dolares | Cod: 9234 | K(PrecioStd)=raw | L=K*O | AC18: 0.97755
A19: gallo-Renta Fija Dolares | B19: Títulos Públicos | C19: BOPREAL S. 1 A VTO31/10/27 U$S CG - Dolar MEP (local) | D19: 9234 | E19: 45768 | G19: Dolar MEP | H19: VENTA USD | I19: -23296 | J19: 98.952 | K19: 98.952 | L19: 98.952 | M19: -23051.858 | N19: 0 | O19: 1 | P19: 1122.08 | Q19: 0 | R19: 0 | T19: 23296 | U19: 0.9799613 | V19: -22829.178 | W19: -23051.858 | X19: 222.67958 | Y19: 0 | Z19: 0 | AA19: SI D19=D18: Z18, SINO: BUSCARV(col V=Precio Nominal (Posicion Inicial Gallo), fallback PrecioTenenciasIniciales/PreciosInicialesEspecies) | U=PrecioPos/P19 | V=-23296*U si venta | W=M-Q | X=|W|-|V| | Y=I+T | Z=Promedio | AB19: Origen: gallo-Renta Fija Dolares | Cod: 9234 | K(PrecioStd)=raw | L=K*O | AC19: 0.98952
A20: Visual | B20: Títulos Públicos | C20: BOPREAL S. 1 B VTO31/10/27 U$S CG - Dolar MEP (local) | D20: 9235 | E20: 45863 | F20: 28/7/2025 | G20: Pesos | H20: Compra Contado | I20: 10519 | J20: 1277.3276 | K20: 127732.76 | L20: 99.327175 | M20: 10448.225 | N20: 0 | O20: 0.00077761707 | P20: 1285.98 | Q20: 349.3414 | R20: 60.645667 | T20: 0 | U20: 0.90691433 | V20: 0 | W20: 10448.225 | X20: 0 | Y20: 10519 | Z20: 0.99327175 | AA20: SI D20=D19: Z19, SINO: BUSCARV(col V=Precio Nominal (Posicion Inicial Gallo), fallback PrecioTenenciasIniciales/PreciosInicialesEspecies) | U=PrecioPos/P20 | V=10519*U si venta | W=M-Q | X=|W|-|V| | Y=I+T | Z=Promedio | AB20: Origen: Visual | Cod: 9235 | K(PrecioStd)=x100 | L=K*O | AC20: 0.99327175
A21: Visual | B21: Títulos Públicos | C21: BOPREAL S.3 VTO31/05/26 U$S CG - Dolar MEP (local) | D21: 9247 | E21: 45863 | F21: 28/7/2025 | G21: Pesos | H21: Venta Contado | I21: -10400 | J21: 1292 | K21: 129200 | L21: 100.46813 | M21: -10448.685 | N21: 0 | O21: 0.00077761707 | P21: 1285.98 | Q21: -349.3568 | R21: 60.64834 | T21: 10400 | U21: 0.55095705 | V21: -5729.9533 | W21: -10099.328 | X21: 4369.3749 | Y21: 0 | Z21: 0 | AA21: SI D21=D20: Z20, SINO: BUSCARV(col V=Precio Nominal (Posicion Inicial Gallo), fallback PrecioTenenciasIniciales/PreciosInicialesEspecies) | U=PrecioPos/P21 | V=-10400*U si venta | W=M-Q | X=|W|-|V| | Y=I+T | Z=Promedio | AB21: Origen: Visual | Cod: 9247 | K(PrecioStd)=x100 | L=K*O | AC21: 1.0046813

Sheet Rentas Dividendos ARS
A1: Instrumento | B1: Cod.Instrum | C1: Categoría | D1: tipo_instrumento | E1: Concertación | F1: Liquidación | G1: Nro. NDC | H1: Tipo Operación | I1: Cantidad | J1: Moneda | K1: Tipo de Cambio | L1: Gastos | M1: Importe | N1: Origen | O1: Importe Original
A2: TRANSPORTADORA DE GAS DEL SUR ORDS. B 1 V | B2: 617 | C2: Dividendos | D2: Acciones | E2: 45819 | F2: 11/6/2025 | G2: 2623 | H2: DIVIDENDO EN EFECTIVO | I2: 0 | J2: Pesos | K2: 1 | L2: 2679.07 | M2: 650746.88 | N2: Visual-Rentas Dividendos ARS | O2: 650746.88
A3: CEDEAR TENARIS S.A.(ADS) | B3: 8524 | C3: Dividendos | D3: Cedears | E3: 45806 | G3: 7174 | H3: DIVIDENDO | I3: 0 | J3: Pesos | K3: 1 | L3: 0 | M3: 86.21 | N3: Gallo-Tit.Privados Exentos | O3: 86.21
A4: CEDEAR TENARIS S.A. (ADS) | B4: 8524 | C4: Dividendos | D4: Cedears | E4: 45996 | F4: 5/12/2025 | G4: 58476 | H4: DIVIDENDO EN EFECTIVO | I4: 0 | J4: Pesos | K4: 1 | L4: 388.51 | M4: 63221.06 | N4: Visual-Rentas Dividendos ARS | O4: 63221.06
A5: ON GENNEIA SA REGS8,75% V.02/09/2027 | B5: 81993 | C5: Rentas | D5: Obligaciones Negociables | E5: 45722 | G5: 3852 | H5: AMORTIZACION | I5: 1500 | J5: Pesos | K5: 1 | L5: 10145.715 | M5: 0 | N5: Gallo-Renta Fija Pesos | ALERTA: MONEDA_EFECTIVA_ARS | O5: 0
A6: ON GENNEIA SA REGS8,75% V.02/09/2027 | B6: 81993 | C6: Rentas | D6: Obligaciones Negociables | E6: 45722 | G6: 3943 | H6: RENTA | I6: 0 | J6: Pesos | K6: 1 | L6: 0 | M6: 393.75 | N6: Gallo-Renta Fija Pesos | ALERTA: MONEDA_EFECTIVA_ARS | O6: 393.75

Sheet Rentas Dividendos USD
A1: Instrumento | B1: Cod.Instrum | C1: Categoría | D1: tipo_instrumento | E1: Concertación | F1: Liquidación | G1: Nro. NDC | H1: Tipo Operación | I1: Cantidad | J1: Moneda | K1: Tipo de Cambio | L1: Gastos | M1: Importe | N1: Origen | O1: Importe Original
A2: BONO REP. ARGENTINA USD STEP UP 2030 | B2: 5921 | C2: Rentas | D2: Títulos Públicos | E2: 45848 | F2: 10/7/2025 | G2: 10668 | H2: AMORTIZACIÓN | I2: 2509.84 | J2: Dolar MEP | K2: 1 | L2: 0 | M2: 0 | N2: Visual-Rentas Dividendos USD | O2: 0
A3: BONO REP. ARGENTINA USD STEP UP 2030 | B3: 5921 | C3: Rentas | D3: Títulos Públicos | E3: 45848 | F3: 10/7/2025 | G3: 10443 | H3: RENTA | I3: 0 | J3: Dolar MEP | K3: 1 | L3: 0.31 | M3: 102.91 | N3: Visual-Rentas Dividendos USD | O3: 102.91
A4: BONO REP. ARGENTINA USD STEP UP 2035 | B4: 5922 | C4: Rentas | D4: Títulos Públicos | E4: 45848 | F4: 10/7/2025 | G4: 11314 | H4: RENTA | I4: 0 | J4: Dolar MEP | K4: 1 | L4: 1.94 | M4: 643.18 | N4: Visual-Rentas Dividendos USD | O4: 643.18
A5: BONO REP ARGENTINA USD 1% 2029 | B5: 5927 | C5: Rentas | D5: Títulos Públicos | E5: 45848 | F5: 10/7/2025 | G5: 10080 | H5: AMORTIZACIÓN | I5: 467.1 | J5: Dolar MEP | K5: 1 | L5: 0 | M5: 0 | N5: Visual-Rentas Dividendos USD | O5: 0
A6: BONO REP ARGENTINA USD 1% 2029 | B6: 5927 | C6: Rentas | D6: Títulos Públicos | E6: 45848 | F6: 10/7/2025 | G6: 10219 | H6: RENTA | I6: 0 | J6: Dolar MEP | K6: 1 | L6: 0.06 | M6: 20.89 | N6: Visual-Rentas Dividendos USD | O6: 20.89
A7: BOPREAL S.3 VTO31/05/26U$S CG | B7: 9247 | C7: Rentas | D7: Títulos Públicos | E7: 45716 | G7: 3654 | H7: RENTA | I7: 0 | J7: Dolar MEP | K7: 1 | L7: 0.83 | M7: 75.43 | N7: Gallo-Renta Fija Dolares | O7: 75.43
A8: BOPREAL S.3 VTO31/05/26 U$S CG | B8: 9247 | C8: Rentas | D8: Títulos Públicos | E8: 45810 | F8: 2/6/2025 | G8: 205 | H8: RENTA | I8: 0 | J8: Dolar MEP | K8: 1 | L8: 0.47 | M8: 77.06 | N8: Visual-Rentas Dividendos USD | O8: 77.06
A9: TD PUB. PCIA. CORDOBAV.27/10/26 | B9: 32804 | C9: Rentas | D9: Títulos Públicos | E9: 45684 | G9: 2656 | H9: RENTA | I9: 0 | J9: Dolar MEP | K9: 1 | L9: 0.66 | M9: 39.41 | N9: Gallo-Renta Fija Dolares | O9: 39.41
A10: TD PUB. PCIA. CORDOBAV.27/10/26 | B10: 32804 | C10: Rentas | D10: Títulos Públicos | E10: 45684 | G10: 2656 | H10: AMORTIZACION | I10: 281.25 | J10: Dolar MEP | K10: 1 | L10: 59.0619 | M10: 0 | N10: Gallo-Renta Fija Dolares | O10: 0
A11: TD PUB. PCIA. CORDOBAV.27/10/26 | B11: 32804 | C11: Rentas | D11: Títulos Públicos | E11: 45775 | G11: 5771 | H11: RENTA | I11: 0 | J11: Dolar MEP | K11: 1 | L11: 0.67 | M11: 34.39 | N11: Gallo-Renta Fija Dolares | O11: 34.39
A12: TD PUB. PCIA. CORDOBAV.27/10/26 | B12: 32804 | C12: Rentas | D12: Títulos Públicos | E12: 45775 | G12: 5771 | H12: AMORTIZACION | I12: 281.25 | J12: Dolar MEP | K12: 1 | L12: 59.0619 | M12: 0 | N12: Gallo-Renta Fija Dolares | O12: 0
A13: TD PUB.PCIA. CORDOBA 1 V.27/10/26 USD CG | B13: 32804 | C13: Rentas | D13: Títulos Públicos | E13: 45866 | F13: 28/7/2025 | G13: 17475 | H13: AMORTIZACIÓN | I13: 545.87 | J13: Dolar MEP | K13: 1 | L13: 0 | M13: 0 | N13: Visual-Rentas Dividendos USD | O13: 0
A14: TD PUB.PCIA. CORDOBA 1 V.27/10/26 USD CG | B14: 32804 | C14: Rentas | D14: Títulos Públicos | E14: 45866 | F14: 28/7/2025 | G14: 17507 | H14: RENTA | I14: 0 | J14: Dolar MEP | K14: 1 | L14: 0.35 | M14: 57.64 | N14: Visual-Rentas Dividendos USD | O14: 57.64
A15: TD PUB.PCIA. CORDOBA 1 V.27/10/26 USD CG | B15: 32804 | C15: Rentas | D15: Títulos Públicos | E15: 45957 | F15: 27/10/2025 | G15: 46291 | H15: RENTA | I15: 0 | J15: Dolar MEP | K15: 1 | L15: 0.29 | M15: 48.03 | N15: Visual-Rentas Dividendos USD | O15: 48.03
A16: TD PUB.PCIA. CORDOBA 1 V.27/10/26 USD CG | B16: 32804 | C16: Rentas | D16: Títulos Públicos | E16: 45957 | F16: 27/10/2025 | G16: 46276 | H16: AMORTIZACIÓN | I16: 545.87 | J16: Dolar MEP | K16: 1 | L16: 0 | M16: 0 | N16: Visual-Rentas Dividendos USD | O16: 0
A17: ON BCO DE VALORES CI. 1 V.11/03/2027 | B17: 58530 | C17: Rentas | D17: Obligaciones Negociables | E17: 45911 | F17: 11/9/2025 | G17: 32213 | H17: RENTA | I17: 0 | J17: Dolar MEP | K17: 1 | L17: 1.82 | M17: 299.54 | N17: Visual-Rentas Dividendos USD | O17: 299.54
A18: BONOS REP. ARG. U$SSTEP UP V.09/07/30 | B18: 81086 | C18: Rentas | D18: Títulos Públicos | E18: 45667 | G18: 2018 | H18: RENTA | I18: 0 | J18: Dolar MEP | K18: 1 | L18: 0.48 | M18: 4.92 | N18: Gallo-Renta Fija Dolares | O18: 4.92
A19: BONOS REP. ARG. U$SSTEP UP V.09/07/30 | B19: 81086 | C19: Rentas | D19: Títulos Públicos | E19: 45667 | G19: 2018 | H19: AMORTIZACION | I19: 120 | J19: Dolar MEP | K19: 1 | L19: 0.4902 | M19: 0 | N19: Gallo-Renta Fija Dolares | O19: 0
A20: BONOS REP. ARG. U$S STEP UP V.09/07/30 | B20: 81086 | C20: Rentas | D20: Títulos Públicos | E20: 45848 | F20: 10/7/2025 | G20: 12454 | H20: AMORTIZACIÓN | I20: 120 | J20: Dolar Cable | K20: 1 | L20: 0 | M20: 0 | N20: Visual-Rentas Dividendos USD | O20: 0
A21: BONOS REP. ARG. U$S STEP UP V.09/07/30 | B21: 81086 | C21: Rentas | D21: Títulos Públicos | E21: 45848 | F21: 10/7/2025 | G21: 12183 | H21: RENTA | I21: 0 | J21: Dolar Cable | K21: 1 | L21: 0.01 | M21: 4.93 | N21: Visual-Rentas Dividendos USD | O21: 4.93
A22: BONOS REP. ARG. U$SSTEP UP V.09/07/35 | B22: 81088 | C22: Rentas | D22: Títulos Públicos | E22: 45667 | G22: 1881 | H22: RENTA | I22: 0 | J22: Dolar MEP | K22: 1 | L22: 35.4 | M22: 31.64 | N22: Gallo-Renta Fija Dolares | O22: -31.64
A23: BONOS REP. ARG. U$S STEP UP V.09/07/35 | B23: 81088 | C23: Rentas | D23: Títulos Públicos | E23: 45848 | F23: 10/7/2025 | G23: 12105 | H23: RENTA | I23: 0 | J23: Dolar Cable | K23: 1 | L23: 13.26 | M23: 4380.4 | N23: Visual-Rentas Dividendos USD | O23: 4380.4
A24: ON GENNEIA SA REGS 8,75% V.02/ | B24: 81993 | C24: Rentas | D24: Obligaciones Negociables | E24: 45903 | F24: 3/9/2025 | G24: 28406 | H24: RENTA | I24: 0 | J24: Dolar Cable | K24: 1 | L24: 1.98 | M24: 324.16 | N24: Visual-Rentas Dividendos USD | O24: 324.16
A25: ON GENNEIA SA REGS 8,75% V.02/ | B25: 81993 | C25: Rentas | D25: Obligaciones Negociables | E25: 45903 | F25: 3/9/2025 | G25: 28387 | H25: AMORTIZACIÓN | I25: 1500 | J25: Dolar Cable | K25: 1 | L25: 0 | M25: 0 | N25: Visual-Rentas Dividendos USD | O25: 0
A26: ON PAMPA ENERGIA SA REGS 9.5% | B26: 82445 | C26: Rentas | D26: Obligaciones Negociables | E26: 45819 | F26: 11/6/2025 | G26: 2701 | H26: RENTA | I26: 0 | J26: Dolar Cable | K26: 1 | L26: 0.77 | M26: 125.76 | N26: Visual-Rentas Dividendos USD | O26: 125.76
A27: TELECOM ARGENT 144A9.5% VTO. 18/07/31 | B27: 83849 | C27: Rentas | D27: Obligaciones Negociables | E27: 45680 | G27: 2595 | H27: RENTA | I27: 0 | J27: Dolar MEP | K27: 1 | L27: 3.87 | M27: 3.47 | N27: Gallo-Renta Fija Dolares | O27: -3.47
A28: TELECOM ARGENT 144A 9.5% VTO. 18/07/31 | B28: 83849 | C28: Rentas | D28: Obligaciones Negociables | E28: 45863 | F28: 25/7/2025 | G28: 17382 | H28: RENTA | I28: 0 | J28: Dolar Cable | K28: 1 | L28: 2.87 | M28: 469.26 | N28: Visual-Rentas Dividendos USD | O28: 469.26
A29: YPF SOCIEDAD ON 8.75%VTO. 11/09/31 | B29: 83928 | C29: Rentas | D29: Obligaciones Negociables | E29: 45730 | G29: 4250 | H29: RENTA | I29: 0 | J29: Dolar MEP | K29: 1 | L29: 4.3 | M29: 3.87 | N29: Gallo-Renta Fija Dolares | O29: -3.87
A30: YPF SOCIEDAD ON 8.75% VTO. 11/09/31 | B30: 83928 | C30: Rentas | D30: Obligaciones Negociables | E30: 45912 | F30: 12/9/2025 | G30: 32485 | H30: RENTA | I30: 0 | J30: Dolar Cable | K30: 1 | L30: 3.21 | M30: 524.7 | N30: Visual-Rentas Dividendos USD | O30: 524.7
